Workbook

Sheet Structure
A1: Institutions Table (2900 rows)
A2: MSEA Org ID | B2: Name | C2: City | D2: State | E2: Zip | F2: Enrollment | G2: Max Credits | H2: Transcription Fee | I2: Can Use For Failed Courses | J2: Can Enrolled Students Use CLEP | K2: Score Validity | L2: CLEP Web URL
A3: ipeds-00001 | B3: SUNY Buffalo | C3: Buffalo | D3: NY | E3: 12345 | F3: 1005 | G3: 30 | H3: 50 | I3: 1 | J3: 0 | K3: varchar | L3: varchar
A5: Contacts Table
A6: cid | B6: MSEA Org ID | C6: First Name | D6: Last Name | E6: Email | F6: Phone | G6: Title
A7: 5 | B7: ipeds-00001 | C7: Ben | D7: Shapiro | E7: ben@sunybuffalo.edu | F7: 716.555.1234 | G7: Registrar
A9: Exams Table (39 rows)
A10: eid | B10: Name
A11: 14 | B11: Biology
A12: 17 | B12: Western Civilization I
A14: Acceptance Table
A15: aid | B15: MSEA Org ID | C15: eid | D15: cut score | E15: credits | F15: related course | G15: updated by | H15: last updated
A16: 1 | B16: ipeds-00001 | C16: 14 | D16: 55 | E16: 3 | F16: BIO 102 | G16: 5 | H16: 45964.475
A17: 2 | B17: ipeds-00001 | C17: 17 | D17: 60 | E17: 4 | F17: 2CIV 105 | G17: 5 | H17: 36526.747
A18: 3 | B18: ipeds-00001 | C18: 14 | D18: 60 | E18: 3 | F18: BIO 102 | G18: 5 | H18: 36526.747

Sheet SAMPLE Table
A1: Institutions Table (~2900 rows)
A2: MSEA Org ID | B2: Name | C2: City | D2: State | E2: Zip | F2: Enrollment | G2: Max Credits | H2: Transcription Fee | I2: Can Use For Failed Courses | J2: Can Enrolled Students Use CLEP | K2: Score Validity (years) | L2: CLEP Web URL
A3: ipeds-196130 | B3: SUNY Buffalo | C3: Buffalo | D3: NY | E3: 12345 | F3: 1005 | G3: 30 | H3: 50 | I3: 1 | J3: 0 | K3: 5 | L3: =lower(left(B3,find(" ",B3)-1))&".edu" -> suny.edu
A4: =VLOOKUP(B4,'Copy of SchoolList'!1:55495,3,false) -> ipeds-165015 | B4: Brandeis University | C4: =VLOOKUP(B4,'Copy of Policies'!1:4624,2,false) -> #REF! | D4: =VLOOKUP(B4,'Copy of Policies'!1:4624,3,false) -> #REF! | E4: 34575 | F4: 16068 | G4: 72 | H4: 0 | I4: 0 | J4: 0 | K4: 4 | L4: =lower(left(B4,find(" ",B4)-1))&".edu" -> brandeis.edu
A5: =VLOOKUP(B5,'Copy of SchoolList'!2:55496,3,false) -> ipeds-130934 | B5: Delaware State University | C5: =VLOOKUP(B5,'Copy of Policies'!2:4625,2,false) -> #REF! | D5: =VLOOKUP(B5,'Copy of Policies'!2:4625,3,false) -> #REF! | E5: 36370 | F5: 27872 | G5: 18 | H5: 5 | I5: 1 | J5: 1 | K5: 6 | L5: =lower(left(B5,find(" ",B5)-1))&".edu" -> delaware.edu
A6: =VLOOKUP(B6,'Copy of SchoolList'!3:55497,3,false) -> ipeds-202523 | B6: Denison University | C6: =VLOOKUP(B6,'Copy of Policies'!3:4626,2,false) -> #REF! | D6: =VLOOKUP(B6,'Copy of Policies'!3:4626,3,false) -> #REF! | E6: 13922 | F6: 51498 | G6: 78 | H6: 10 | I6: 1 | J6: 1 | K6: 10 | L6: =lower(left(B6,find(" ",B6)-1))&".edu" -> denison.edu
A7: =VLOOKUP(B7,'Copy of SchoolList'!4:55498,3,false) -> ipeds-144740 | B7: DePaul University | C7: =VLOOKUP(B7,'Copy of Policies'!4:4627,2,false) -> #REF! | D7: =VLOOKUP(B7,'Copy of Policies'!4:4627,3,false) -> #REF! | E7: 51059 | F7: 949 | G7: 93 | H7: 15 | I7: 1 | J7: 0 | K7: 6 | L7: =lower(left(B7,find(" ",B7)-1))&".edu" -> depaul.edu
A8: =VLOOKUP(B8,'Copy of SchoolList'!5:55499,3,false) -> ipeds-212054 | B8: Drexel University | C8: =VLOOKUP(B8,'Copy of Policies'!5:4628,2,false) -> #REF! | D8: =VLOOKUP(B8,'Copy of Policies'!5:4628,3,false) -> #REF! | E8: 62026 | F8: 48035 | G8: 63 | H8: 20 | I8: 1 | J8: 0 | K8: 3 | L8: =lower(left(B8,find(" ",B8)-1))&".edu" -> drexel.edu
A9: =VLOOKUP(B9,'Copy of SchoolList'!6:55500,3,false) -> ipeds-171100 | B9: Michigan State University | C9: =VLOOKUP(B9,'Copy of Policies'!6:4629,2,false) -> #REF! | D9: =VLOOKUP(B9,'Copy of Policies'!6:4629,3,false) -> #REF! | E9: 14530 | F9: 42442 | G9: 15 | H9: 15 | I9: 0 | J9: 1 | K9: 7 | L9: =lower(left(B9,find(" ",B9)-1))&".edu" -> michigan.edu
A10: =VLOOKUP(B10,'Copy of SchoolList'!7:55501,3,false) -> ipeds-185828 | B10: New Jersey Institute Of Technology | C10: =VLOOKUP(B10,'Copy of Policies'!7:4630,2,false) -> #REF! | D10: =VLOOKUP(B10,'Copy of Policies'!7:4630,3,false) -> #REF! | E10: 17123 | F10: 44395 | G10: 42 | H10: 20 | I10: 0 | J10: 1 | K10: 2 | L10: =lower(left(B10,find(" ",B10)-1))&".edu" -> new.edu
A11: =VLOOKUP(B11,'Copy of SchoolList'!8:55502,3,false) -> ipeds-193900 | B11: New York University | C11: =VLOOKUP(B11,'Copy of Policies'!8:4631,2,false) -> #REF! | D11: =VLOOKUP(B11,'Copy of Policies'!8:4631,3,false) -> #REF! | E11: 42608 | F11: 46504 | G11: 18 | H11: 15 | I11: 0 | J11: 0 | K11: 4 | L11: =lower(left(B11,find(" ",B11)-1))&".edu" -> new.edu
A12: =VLOOKUP(B12,'Copy of SchoolList'!9:55503,3,false) -> ipeds-204635 | B12: Ohio Northern University | C12: =VLOOKUP(B12,'Copy of Policies'!9:4632,2,false) -> #REF! | D12: =VLOOKUP(B12,'Copy of Policies'!9:4632,3,false) -> #REF! | E12: 25627 | F12: 46867 | G12: 12 | H12: 10 | I12: 1 | J12: 1 | K12: 4 | L12: =lower(left(B12,find(" ",B12)-1))&".edu" -> ohio.edu
A13: ipeds-204796 | B13: Ohio State University | C13: =VLOOKUP(B13,'Copy of Policies'!10:4633,2,false) -> #REF! | D13: =VLOOKUP(B13,'Copy of Policies'!10:4633,3,false) -> #REF! | E13: 33303 | F13: 17926 | G13: 21 | H13: 5 | I13: 1 | J13: 1 | K13: 9 | L13: =lower(left(B13,find(" ",B13)-1))&".edu" -> ohio.edu
A14: =VLOOKUP(B14,'Copy of SchoolList'!11:55505,3,false) -> ipeds-163851 | B14: Salisbury University | C14: =VLOOKUP(B14,'Copy of Policies'!11:4634,2,false) -> #REF! | D14: =VLOOKUP(B14,'Copy of Policies'!11:4634,3,false) -> #REF! | E14: 39686 | F14: 8753 | G14: 66 | H14: 50 | I14: 1 | J14: 1 | K14: 6 | L14: =lower(left(B14,find(" ",B14)-1))&".edu" -> salisbury.edu
A15: =VLOOKUP(B15,'Copy of SchoolList'!12:55506,3,false) -> ipeds-196413 | B15: Syracuse University | C15: =VLOOKUP(B15,'Copy of Policies'!12:4635,2,false) -> #REF! | D15: =VLOOKUP(B15,'Copy of Policies'!12:4635,3,false) -> #REF! | E15: 54481 | F15: 24525 | G15: 21 | H15: 45 | I15: 0 | J15: 0 | K15: 8 | L15: =lower(left(B15,find(" ",B15)-1))&".edu" -> syracuse.edu
A16: =VLOOKUP(B16,'Copy of SchoolList'!13:55507,3,false) -> ipeds-216339 | B16: Temple University | C16: =VLOOKUP(B16,'Copy of Policies'!13:4636,2,false) -> #REF! | D16: =VLOOKUP(B16,'Copy of Policies'!13:4636,3,false) -> #REF! | E16: 71632 | F16: 41542 | G16: 66 | H16: 40 | I16: 0 | J16: 0 | K16: 9 | L16: =lower(left(B16,find(" ",B16)-1))&".edu" -> temple.edu
A17: =VLOOKUP(B17,'Copy of SchoolList'!14:55508,3,false) -> ipeds-164076 | B17: Towson University | C17: =VLOOKUP(B17,'Copy of Policies'!14:4637,2,false) -> #REF! | D17: =VLOOKUP(B17,'Copy of Policies'!14:4637,3,false) -> #REF! | E17: 98918 | F17: 42752 | G17: 24 | H17: 35 | I17: 0 | J17: 1 | K17: 1 | L17: =lower(left(B17,find(" ",B17)-1))&".edu" -> towson.edu
A18: =VLOOKUP(B18,'Copy of SchoolList'!15:55509,3,false) -> ipeds-168148 | B18: Tufts University | C18: =VLOOKUP(B18,'Copy of Policies'!15:4638,2,false) -> #REF! | D18: =VLOOKUP(B18,'Copy of Policies'!15:4638,3,false) -> #REF! | E18: 46386 | F18: 11273 | G18: 24 | H18: 30 | I18: 1 | J18: 0 | K18: 10 | L18: =lower(left(B18,find(" ",B18)-1))&".edu" -> tufts.edu
A19: =VLOOKUP(B19,'Copy of SchoolList'!16:55510,3,false) -> ipeds-132903 | B19: University Of Central Florida | C19: =VLOOKUP(B19,'Copy of Policies'!16:4639,2,false) -> #REF! | D19: =VLOOKUP(B19,'Copy of Policies'!16:4639,3,false) -> #REF! | E19: 41755 | F19: 38702 | G19: 45 | H19: 25 | I19: 1 | J19: 1 | K19: 8 | L19: =lower(left(B19,find(" ",B19)-1))&".edu" -> university.edu
A20: =VLOOKUP(B20,'Copy of SchoolList'!17:55511,3,false) -> ipeds-202480 | B20: University Of Dayton | C20: =VLOOKUP(B20,'Copy of Policies'!17:4640,2,false) -> #REF! | D20: =VLOOKUP(B20,'Copy of Policies'!17:4640,3,false) -> #REF! | E20: 60512 | F20: 18899 | G20: 36 | H20: 20 | I20: 0 | J20: 0 | K20: 2 | L20: =lower(left(B20,find(" ",B20)-1))&".edu" -> university.edu
A21: =VLOOKUP(B21,'Copy of SchoolList'!18:55512,3,false) -> ipeds-130943 | B21: University of Delaware | C21: =VLOOKUP(B21,'Copy of Policies'!18:4641,2,false) -> #REF! | D21: =VLOOKUP(B21,'Copy of Policies'!18:4641,3,false) -> #REF! | E21: 24753 | F21: 29813 | G21: 3 | H21: 15 | I21: 1 | J21: 0 | K21: 6 | L21: =lower(left(B21,find(" ",B21)-1))&".edu" -> university.edu
A22: ipeds-170976 | B22: University of Michigan | C22: =VLOOKUP(B22,'Copy of Policies'!19:4642,2,false) -> #REF! | D22: =VLOOKUP(B22,'Copy of Policies'!19:4642,3,false) -> #REF! | E22: 10463 | F22: 36190 | G22: 78 | H22: 10 | I22: 0 | J22: 0 | K22: 5 | L22: =lower(left(B22,find(" ",B22)-1))&".edu" -> university.edu
A23: =VLOOKUP(B23,'Copy of SchoolList'!20:55514,3,false) -> ipeds-221999 | B23: Vanderbilt University | C23: =VLOOKUP(B23,'Copy of Policies'!20:4643,2,false) -> #REF! | D23: =VLOOKUP(B23,'Copy of Policies'!20:4643,3,false) -> #REF! | E23: 51923 | F23: 26933 | G23: 3 | H23: 15 | I23: 1 | J23: 1 | K23: 8 | L23: =lower(left(B23,find(" ",B23)-1))&".edu" -> vanderbilt.edu
A24: ipeds-206604 | B24: Wright State University | C24: =VLOOKUP(B24,'Copy of Policies'!21:4644,2,false) -> #REF! | D24: =VLOOKUP(B24,'Copy of Policies'!21:4644,3,false) -> #REF! | E24: 36374 | F24: 6451 | G24: 39 | H24: 20 | I24: 1 | J24: 1 | K24: 9 | L24: =lower(left(B24,find(" ",B24)-1))&".edu" -> wright.edu
A26: Contacts Table
A27: cid | B27: MSEA Org ID | C27: First Name | D27: Last Name | E27: Email | F27: Phone | G27: Title
A28: 5 | B28: ipeds-196130 | C28: Ben | D28: Shapiro | E28: ben@sunybuffalo.edu | F28: 716.555.1234 | G28: Registrar
A29: 6 | B29: ipeds-196130 | C29: John | D29: Smith | E29: john@sunybuffalo.edu | F29: 716.555.1235 | G29: Registrar
A30: 7 | B30: ipeds-204796 | C30: Shaun | D30: Yoder | E30: shaun@theohio.edu | F30: 614.867.5309 | G30: Registrar
A32: Exams Table (39 rows)
A33: eid | B33: Name
A34: 1 | B34: American Government
A35: 2 | B35: American Literature
A36: 3 | B36: Analyzing and Interpreting Literature
A37: 4 | B37: Biology
A38: 5 | B38: Calculus
A39: 6 | B39: Chemistry
A40: 7 | B40: College Algebra
A41: 8 | B41: College Composition
A42: 9 | B42: College Composition Modular
...

Sheet Sample Data
A1: School Name | B1: City | C1: State | D1: DI Code | E1: Humanities | F1: American Government | G1: History of the United States I | H1: History of the United States II | I1: Introductory Sociology | J1: Social Sciences and History | K1: Western Civilization I | L1: Western Civilization II | M1: College Composition | N1: College Composition Modular | O1: American Literature | P1: Analyzing and Interpreting Literature | Q1: English Literature | R1: Human Growth and Development | S1: Introduction to Educational Psychology | T1: Introductory Psychology | U1: Principles of Macroeconomics | V1: Principles of Microeconomics | W1: Biology | X1: Chemistry | Y1: Natural Sciences | Z1: Calculus | AA1: College Algebra | AB1: College Mathematics | AC1: Precalculus | AD1: French Language Level I | AE1: French Language Level II | AF1: German Language Level I | AG1: German Language Level II | AH1: Spanish Language Level I | AI1: Spanish Language Level II | AJ1: Financial Accounting | AK1: Information Systems | AL1: Introductory Business Law | AM1: Principles of Management | AN1: Principles of Marketing | AO1: Spanish With Writing Level I | AP1: Spanish With Writing Level II | AQ1: Break | AR1: Humanities | AS1: American Government | AT1: History of the United States I | AU1: History of the United States II | AV1: Introductory Sociology | AW1: Social Sciences and History | AX1: Western Civilization I | AY1: Western Civilization II | AZ1: College Composition | BA1: College Composition Modular | BB1: American Literature | BC1: Analyzing and Interpreting Literature | BD1: English Literature | BE1: Human Growth and Development | BF1: Introduction to Educational Psychology | BG1: Introductory Psychology | BH1: Principles of Macroeconomics | BI1: Principles of Microeconomics | BJ1: Biology | BK1: Chemistry | BL1: Natural Sciences | BM1: Calculus | BN1: College Algebra | BO1: College Mathematics | BP1: Precalculus | BQ1: French Language Level I | BR1: French Language Level II | BS1: German Language Level I | BT1: German Language Level II | BU1: Spanish Language Level I | BV1: Spanish Language Level II | BW1: Financial Accounting | BX1: Information Systems | BY1: Introductory Business Law | BZ1: Principles of Management | CA1: Principles of Marketing | CB1: Spanish With Writing Level I | CC1: Spanish With Writing Level II | CD1: Notes | CE1: Humanities | CF1: American Government | CG1: History of the United States I | CH1: History of the United States II | CI1: Introductory Sociology | CJ1: Social Sciences and History | CK1: Western Civilization I | CL1: Western Civilization II | CM1: College Composition | CN1: College Composition Modular | CO1: American Literature | CP1: Analyzing and Interpreting Literature | CQ1: English Literature | CR1: Human Growth and Development | CS1: Introduction to Educational Psychology | CT1: Introductory Psychology | CU1: Principles of Macroeconomics | CV1: Principles of Microeconomics | CW1: Biology | CX1: Chemistry | CY1: Natural Sciences | CZ1: Calculus | DA1: College Algebra | DB1: College Mathematics | DC1: Precalculus | DD1: French Language Level I | DE1: French Language Level II | DF1: German Language Level I | DG1: German Language Level II | DH1: Spanish Language Level I | DI1: Spanish Language Level II | DJ1: Financial Accounting | DK1: Information Systems | DL1: Introductory Business Law | DM1: Principles of Management | DN1: Principles of Marketing | DO1: Spanish With Writing Level I | DP1: Spanish With Writing Level II
A2: Berea College | B2: Berea | C2: KY | D2: 1060 | E2: 0 | F2: 55 | G2: 52 | H2: 53 | I2: 52 | J2: 0 | K2: 52 | L2: 52 | M2: 50 | N2: 50 | O2: 50 | P2: 56 | Q2: 50 | R2: 52 | S2: 0 | T2: 52 | U2: 50 | V2: 50 | W2: 50 | X2: 58 | Y2: 0 | Z2: 51 | AA2: 51 | AB2: 0 | AC2: 0 | AD2: 50 | AE2: 56 | AF2: 50 | AG2: 60 | AH2: 50 | AI2: 60 | AJ2: 0 | AK2: 56 | AL2: 57 | AM2: 52 | AN2: 55 | AO2: 0 | AP2: 0 | AR2: 0 | AS2: 4 | AT2: 4 | AU2: 4 | AV2: 4 | AW2: 0 | AX2: 4 | AY2: 4 | AZ2: 6 | BA2: 3 | BB2: 4 | BC2: 4 | BD2: 4 | BE2: 4 | BF2: 0 | BG2: 4 | BH2: 4 | BI2: 4 | BJ2: 4 | BK2: 4 | BL2: 0 | BM2: 4 | BN2: 4 | BO2: 0 | BP2: 0 | BQ2: 4 | BR2: 4 | BS2: 4 | BT2: 4 | BU2: 4 | BV2: 4 | BW2: 0 | BX2: 4 | BY2: 4 | BZ2: 4 | CA2: 4 | CB2: 0 | CC2: 0 | CE2: 0 | CF2: 0 | CG2: 0 | CH2: 0 | CI2: 0 | CJ2: 0 | CK2: 0 | CL2: 0 | CM2: 0 | CN2: 0 | CO2: 0 | CP2: 0 | CQ2: 0 | CR2: 0 | CS2: 0 | CT2: 0 | CU2: 0 | CV2: 0 | CW2: 0 | CX2: 0 | CY2: 0 | CZ2: 0 | DA2: 0 | DB2: 0 | DC2: 0 | DD2: 0 | DE2: 0 | DF2: 0 | DG2: 0 | DH2: 0 | DI2: 0 | DJ2: 0 | DK2: 0 | DL2: 0 | DM2: 0 | DN2: 0 | DO2: 0 | DP2: 0
A3: Brandeis University | B3: Waltham | C3: MA | D3: 3092 | E3: 0 | F3: 0 | G3: 0 | H3: 0 | I3: 0 | J3: 0 | K3: 0 | L3: 0 | M3: 0 | N3: 0 | O3: 0 | P3: 0 | Q3: 0 | R3: 0 | S3: 0 | T3: 0 | U3: 0 | V3: 0 | W3: 0 | X3: 0 | Y3: 0 | Z3: 0 | AA3: 0 | AB3: 0 | AC3: 0 | AD3: 0 | AE3: 0 | AF3: 0 | AG3: 0 | AH3: 0 | AI3: 0 | AJ3: 0 | AK3: 0 | AL3: 0 | AM3: 0 | AN3: 0 | AO3: 0 | AP3: 0 | AR3: 0 | AS3: 0 | AT3: 0 | AU3: 0 | AV3: 0 | AW3: 0 | AX3: 0 | AY3: 0 | AZ3: 0 | BA3: 0 | BB3: 0 | BC3: 0 | BD3: 0 | BE3: 0 | BF3: 0 | BG3: 0 | BH3: 0 | BI3: 0 | BJ3: 0 | BK3: 0 | BL3: 0 | BM3: 0 | BN3: 0 | BO3: 0 | BP3: 0 | BQ3: 0 | BR3: 0 | BS3: 0 | BT3: 0 | BU3: 0 | BV3: 0 | BW3: 0 | BX3: 0 | BY3: 0 | BZ3: 0 | CA3: 0 | CB3: 0 | CC3: 0 | CE3: 0 | CF3: 0 | CG3: 0 | CH3: 0 | CI3: 0 | CJ3: 0 | CK3: 0 | CL3: 0 | CM3: 0 | CN3: 0 | CO3: 0 | CP3: 0 | CQ3: 0 | CR3: 0 | CS3: 0 | CT3: 0 | CU3: 0 | CV3: 0 | CW3: 0 | CX3: 0 | CY3: 0 | CZ3: 0 | DA3: 0 | DB3: 0 | DC3: 0 | DD3: 0 | DE3: 0 | DF3: 0 | DG3: 0 | DH3: 0 | DI3: 0 | DJ3: 0 | DK3: 0 | DL3: 0 | DM3: 0 | DN3: 0 | DO3: 0 | DP3: 0
A4: Cornell University School of Nursing | B4: New York | C4: NY | D4: 2119 | E4: 0 | F4: 0 | G4: 0 | H4: 0 | I4: 0 | J4: 0 | K4: 0 | L4: 0 | M4: 0 | N4: 0 | O4: 0 | P4: 0 | Q4: 0 | R4: 0 | S4: 0 | T4: 0 | U4: 0 | V4: 0 | W4: 0 | X4: 0 | Y4: 0 | Z4: 0 | AA4: 0 | AB4: 0 | AC4: 0 | AD4: 0 | AE4: 0 | AF4: 0 | AG4: 0 | AH4: 0 | AI4: 0 | AJ4: 0 | AK4: 0 | AL4: 0 | AM4: 0 | AN4: 0 | AO4: 0 | AP4: 0 | AR4: 0 | AS4: 0 | AT4: 0 | AU4: 0 | AV4: 0 | AW4: 0 | AX4: 0 | AY4: 0 | AZ4: 0 | BA4: 0 | BB4: 0 | BC4: 0 | BD4: 0 | BE4: 0 | BF4: 0 | BG4: 0 | BH4: 0 | BI4: 0 | BJ4: 0 | BK4: 0 | BL4: 0 | BM4: 0 | BN4: 0 | BO4: 0 | BP4: 0 | BQ4: 0 | BR4: 0 | BS4: 0 | BT4: 0 | BU4: 0 | BV4: 0 | BW4: 0 | BX4: 0 | BY4: 0 | BZ4: 0 | CA4: 0 | CB4: 0 | CC4: 0 | CE4: 0 | CF4: 0 | CG4: 0 | CH4: 0 | CI4: 0 | CJ4: 0 | CK4: 0 | CL4: 0 | CM4: 0 | CN4: 0 | CO4: 0 | CP4: 0 | CQ4: 0 | CR4: 0 | CS4: 0 | CT4: 0 | CU4: 0 | CV4: 0 | CW4: 0 | CX4: 0 | CY4: 0 | CZ4: 0 | DA4: 0 | DB4: 0 | DC4: 0 | DD4: 0 | DE4: 0 | DF4: 0 | DG4: 0 | DH4: 0 | DI4: 0 | DJ4: 0 | DK4: 0 | DL4: 0 | DM4: 0 | DN4: 0 | DO4: 0 | DP4: 0
A5: Delaware State University | B5: Dover | C5: DE | D5: 5153 | E5: 59 | F5: 59 | G5: 59 | H5: 59 | I5: 59 | J5: 59 | K5: 59 | L5: 59 | M5: 63 | N5: 72 | O5: 59 | P5: 59 | Q5: 59 | R5: 59 | S5: 59 | T5: 59 | U5: 60 | V5: 60 | W5: 60 | X5: 60 | Y5: 60 | Z5: 60 | AA5: 60 | AB5: 60 | AC5: 59 | AD5: 59 | AE5: 63 | AF5: 60 | AG5: 72 | AH5: 59 | AI5: 63 | AJ5: 59 | AK5: 63 | AL5: 59 | AM5: 60 | AN5: 60 | AO5: 0 | AP5: 0 | AR5: 6 | AS5: 3 | AT5: 3 | AU5: 3 | AV5: 3 | AW5: 3 | AX5: 3 | AY5: 3 | AZ5: 3 | BA5: 6 | BB5: 3 | BC5: 3 | BD5: 3 | BE5: 3 | BF5: 3 | BG5: 3 | BH5: 3 | BI5: 3 | BJ5: 3 | BK5: 3 | BL5: 3 | BM5: 3 | BN5: 3 | BO5: 3 | BP5: 3 | BQ5: 3 | BR5: 6 | BS5: 3 | BT5: 6 | BU5: 3 | BV5: 6 | BW5: 3 | BX5: 3 | BY5: 3 | BZ5: 3 | CA5: 3 | CB5: 0 | CC5: 0 | CE5: 0 | CF5: 0 | CG5: 0 | CH5: 0 | CI5: 0 | CJ5: 0 | CK5: 0 | CL5: 0 | CM5: 0 | CN5: 0 | CO5: 0 | CP5: 0 | CQ5: 0 | CR5: 0 | CS5: 0 | CT5: 0 | CU5: 0 | CV5: 0 | CW5: 0 | CX5: 0 | CY5: 0 | CZ5: 0 | DA5: 0 | DB5: 0 | DC5: 0 | DD5: 0 | DE5: 0 | DF5: 0 | DG5: 0 | DH5: 0 | DI5: 0 | DJ5: 0 | DK5: 0 | DL5: 0 | DM5: 0 | DN5: 0 | DO5: 0 | DP5: 0
A6: Denison University | B6: Granville | C6: OH | D6: 1164 | E6: 0 | F6: 60 | G6: 60 | H6: 60 | I6: 60 | J6: 0 | K6: 60 | L6: 60 | M6: 0 | N6: 0 | O6: 60 | P6: 60 | Q6: 60 | R6: 0 | S6: 60 | T6: 0 | U6: 0 | V6: 0 | W6: 60 | X6: 60 | Y6: 0 | Z6: 60 | AA6: 60 | AB6: 0 | AC6: 0 | AD6: 60 | AE6: 60 | AF6: 60 | AG6: 60 | AH6: 60 | AI6: 60 | AJ6: 0 | AK6: 60 | AL6: 0 | AM6: 0 | AN6: 0 | AO6: 0 | AP6: 0 | AR6: 0 | AS6: 4 | AT6: 4 | AU6: 4 | AV6: 4 | AW6: 0 | AX6: 4 | AY6: 4 | AZ6: 0 | BA6: 0 | BB6: 4 | BC6: 4 | BD6: 4 | BE6: 0 | BF6: 4 | BG6: 0 | BH6: 0 | BI6: 0 | BJ6: 4 | BK6: 4 | BL6: 0 | BM6: 4 | BN6: 4 | BO6: 0 | BP6: 0 | BQ6: 4 | BR6: 4 | BS6: 4 | BT6: 4 | BU6: 4 | BV6: 4 | BW6: 0 | BX6: 4 | BY6: 0 | BZ6: 0 | CA6: 0 | CB6: 0 | CC6: 0 | CE6: 0 | CF6: 0 | CG6: 0 | CH6: 0 | CI6: 0 | CJ6: 0 | CK6: 0 | CL6: 0 | CM6: 0 | CN6: 0 | CO6: 0 | CP6: 0 | CQ6: 0 | CR6: 0 | CS6: 0 | CT6: 0 | CU6: 0 | CV6: 0 | CW6: 0 | CX6: 0 | CY6: 0 | CZ6: 0 | DA6: 0 | DB6: 0 | DC6: 0 | DD6: 0 | DE6: 0 | DF6: 0 | DG6: 0 | DH6: 0 | DI6: 0 | DJ6: 0 | DK6: 0 | DL6: 0 | DM6: 0 | DN6: 0 | DO6: 0 | DP6: 0
A7: Purdue University - Fort Wayne | B7: Fort Wayne | C7: IN | D7: 1336 | E7: No Score Given | F7: 50 | G7: No Score Given | H7: No Score Given | I7: No Score Given | J7: No Score Given | K7: No Score Given | L7: No Score Given | M7: No Score Given | N7: No Score Given | O7: No Score Given | P7: No Score Given | Q7: No Score Given | R7: 50 | S7: No Score Given | T7: 50 | U7: No Score Given | V7: No Score Given | W7: 55/61 | X7: 50/60/70 | Y7: No Score Given | Z7: 50 | AA7: 50 | AB7: 50 | AC7: 50 | AD7: 50 | AE7: 52 | AF7: 50 | AG7: 63 | AH7: 50 | AI7: 54 | AJ7: No Score Given | AK7: 50 | AL7: No Score Given | AM7: 50 | AN7: No Score Given | AO7: 0 | AP7: 0 | AR7: No Credit Given | AS7: 3 | AT7: No Credit Given | AU7: No Credit Given | AV7: No Credit Given | AW7: No Credit Given | AX7: No Credit Given | AY7: No Credit Given | AZ7: No Credit Given | BA7: No Credit Given | BB7: No Credit Given | BC7: No Credit Given | BD7: No Credit Given | BE7: 3 | BF7: No Credit Given | BG7: 3 | BH7: No Credit Given | BI7: No Credit Given | BJ7: 4/8 | BK7: 3/4/8 | BL7: No Credit Given | BM7: 4 | BN7: 3 | BO7: 3 | BP7: 5 | BQ7: 8 | BR7: 14 | BS7: 8 | BT7: 14 | BU7: 8 | BV7: 14 | BW7: No Credit Given | BX7: 3 | BY7: No Credit Given | BZ7: 3 | CA7: No Credit Given | CB7: 0 | CC7: 0 | CE7: 0 | CF7: No Course Given | CG7: POLS Y103 | CH7: No Course Given | CI7: No Course Given | CJ7: No Course Given | CK7: No Course Given | CL7: No Course Given | CM7: No Course Given | CN7: No Course Given | CO7: No Course Given | CP7: No Course Given | CQ7: No Course Given | CR7: No Course Given | CS7: PSY 36900 | CT7: No Course Given | CU7: PSY 12000 | CV7: No Course Given | CW7: No Course Given | CX7: BIOL 11700/BIOL 11700, BIOL 11900 | CY7: CHM 11100/CHM 11500/CHM 11500, CHM 11600 | CZ7: No Course Given | DA7: MA 16500 | DB7: MA 15300 | DC7: MA 16800 or STAT 12500 or MA 17500 | DD7: MA 15900 | DE7: FREN F111, FREN F112 | DF7: FREN F111, FREN F112, FREN F203, FREN F204 | DG7: GER G111, GER G112 | DH7: GER G111, GER G112, GER G203, GER G204 | DI7: SPAN S111, SPAN S112 | DJ7: SPAN S111, SPAN S112, SPAN S203, SPAN S204 | DK7: No Course Given | DL7: ETCS 10600 | DM7: No Course Given | DN7: BUS W100 | DO7: No Course Given | DP7: 0
A8: DePaul University | B8: Chicago | C8: IL | D8: 1165 | E8: 50 | F8: 55 | G8: 0 | H8: 0 | I8: 50 | J8: 0 | K8: 0 | L8: 0 | M8: 0 | N8: 0 | O8: 55 | P8: 55 | Q8: 0 | R8: 50 | S8: 50 | T8: 50 | U8: 55 | V8: 55 | W8: 53 | X8: 50/63 | Y8: 0 | Z8: 50 | AA8: 50 | AB8: 0 | AC8: 0 | AD8: 50 | AE8: 60/70/79 | AF8: 50 | AG8: 60/70/79 | AH8: 50 | AI8: 60/70/79 | AJ8: 50 | AK8: 52 | AL8: 50 | AM8: 50 | AN8: 50 | AO8: 0 | AP8: 0 | AR8: 4 | AS8: 4 | AT8: 0 | AU8: 0 | AV8: 4 | AW8: 0 | AX8: 0 | AY8: 0 | AZ8: 0 | BA8: 0 | BB8: 4 | BC8: 4 | BD8: 0 | BE8: 4 | BF8: 4 | BG8: 8 | BH8: 4 | BI8: 4 | BJ8: 12 | BK8: 4/8 | BL8: 0 | BM8: 4 | BN8: 4 | BO8: 0 | BP8: 0 | BQ8: 4 | BR8: 8/12/16 | BS8: 4 | BT8: 8/12/16 | BU8: 4 | BV8: 8/12/16 | BW8: 4 | BX8: 4 | BY8: 4 | BZ8: 4 | CA8: 4 | CB8: 0 | CC8: 0 | CE8: 0 | CF8: 0 | CG8: 0 | CH8: 0 | CI8: 0 | CJ8: 0 | CK8: 0 | CL8: 0 | CM8: 0 | CN8: 0 | CO8: 0 | CP8: 0 | CQ8: 0 | CR8: 0 | CS8: 0 | CT8: 0 | CU8: 0 | CV8: 0 | CW8: 0 | CX8: 0 | CY8: 0 | CZ8: 0 | DA8: 0 | DB8: 0 | DC8: 0 | DD8: 0 | DE8: 0 | DF8: 0 | DG8: 0 | DH8: 0 | DI8: 0 | DJ8: 0 | DK8: 0 | DL8: 0 | DM8: 0 | DN8: 0 | DO8: 0 | DP8: 0
A9: Drexel University | B9: Philadelphia | C9: PA | D9: 2194 | E9: 0 | F9: 50 | G9: 50 | H9: 50 | I9: 50 | J9: 0 | K9: 50 | L9: 50 | M9: 0 | N9: 0 | O9: 60 | P9: 55 | Q9: 57 | R9: 50 | S9: 50 | T9: 50 | U9: 48 | V9: 47 | W9: 50 | X9: 50 | Y9: 0 | Z9: 47 | AA9: 45 | AB9: 0 | AC9: 0 | AD9: 0 | AE9: 0 | AF9: 0 | AG9: 0 | AH9: 0 | AI9: 0 | AJ9: 0 | AK9: 52 | AL9: 51 | AM9: 0 | AN9: 0 | AO9: 0 | AP9: 0 | AR9: 0 | AS9: 4 | AT9: 3 | AU9: 3 | AV9: 3 | AW9: 0 | AX9: 3 | AY9: 3 | AZ9: 0 | BA9: 0 | BB9: 6 | BC9: 6 | BD9: 9 | BE9: 3 | BF9: 3 | BG9: 3 | BH9: 4 | BI9: 4 | BJ9: 8 | BK9: 8 | BL9: 0 | BM9: 8 | BN9: 4 | BO9: 0 | BP9: 0 | BQ9: 0 | BR9: 0 | BS9: 0 | BT9: 0 | BU9: 0 | BV9: 0 | BW9: 0 | BX9: 3 | BY9: 4 | BZ9: 0 | CA9: 0 | CB9: 0 | CC9: 0 | CE9: 0 | CF9: 0 | CG9: 0 | CH9: 0 | CI9: 0 | CJ9: 0 | CK9: 0 | CL9: 0 | CM9: 0 | CN9: 0 | CO9: 0 | CP9: 0 | CQ9: 0 | CR9: 0 | CS9: 0 | CT9: 0 | CU9: 0 | CV9: 0 | CW9: 0 | CX9: 0 | CY9: 0 | CZ9: 0 | DA9: 0 | DB9: 0 | DC9: 0 | DD9: 0 | DE9: 0 | DF9: 0 | DG9: 0 | DH9: 0 | DI9: 0 | DJ9: 0 | DK9: 0 | DL9: 0 | DM9: 0 | DN9: 0 | DO9: 0 | DP9: 0
A10: Miami University - Oxford | B10: Oxford | C10: OH | D10: 1463 | E10: 55 | F10: 56 | G10: 61 | H10: 57 | I10: 56 | J10: 63 | K10: 55 | L10: 54 | M10: 0 | N10: 0 | O10: 53 | P10: 59 | Q10: 63 | R10: 58 | S10: 62 | T10: 55 | U10: 56 | V10: 57 | W10: 50 | X10: 50 | Y10: 0 | Z10: 64 | AA10: 63 | AB10: 63 | AC10: 0 | AD10: 55 | AE10: 65 | AF10: 59 | AG10: 67 | AH10: 56 | AI10: 63 | AJ10: 65 | AK10: 50 | AL10: 57 | AM10: 0 | AN10: 0 | AO10: 0 | AP10: 0 | AR10: 3 | AS10: 3 | AT10: 3 | AU10: 3 | AV10: 3 | AW10: 3 | AX10: 3 | AY10: 3 | AZ10: 0 | BA10: 0 | BB10: 3 | BC10: 3 | BD10: 3 | BE10: 3 | BF10: 3 | BG10: 3 | BH10: 3 | BI10: 3 | BJ10: 3 | BK10: 3 | BL10: 0 | BM10: 5 | BN10: 3 | BO10: 3 | BP10: 0 | BQ10: 8 | BR10: 14 | BS10: 8 | BT10: 11 | BU10: 8 | BV10: 11 | BW10: 3 | BX10: 3 | BY10: 3 | BZ10: 0 | CA10: 0 | CB10: 0 | CC10: 0 | CD10: 0 | CE10: 0 | CF10: 0 | CG10: 0 | CH10: 0 | CI10: 0 | CJ10: 0 | CK10: 0 | CL10: 0 | CM10: 0 | CN10: 0 | CO10: 0 | CP10: 0 | CQ10: 0 | CR10: 0 | CS10: 0 | CT10: 0 | CU10: 0 | CV10: 0 | CW10: 0 | CX10: 0 | CY10: 0 | CZ10: 0 | DA10: 0 | DB10: 0 | DC10: 0 | DD10: 0 | DE10: 0 | DF10: 0 | DG10: 0 | DH10: 0 | DI10: 0 | DJ10: 0 | DK10: 0 | DL10: 0 | DM10: 0 | DN10: 0 | DO10: 0 | DP10: 0
A11: Michigan State University | B11: East Lansing | C11: MI | D11: 1465 | E11: 50 | F11: 50 | G11: 50 | H11: 50 | I11: 50 | J11: 50 | K11: 50 | L11: 50 | M11: 0 | N11: 0 | O11: 50 | P11: 50 | Q11: 50 | R11: 50 | S11: 50 | T11: 50 | U11: 50 | V11: 50 | W11: 50 | X11: 50 | Y11: 50 | Z11: 50 | AA11: 50 | AB11: 0 | AC11: 50 | AD11: 50 | AE11: 59 | AF11: 50 | AG11: 63 | AH11: 50 | AI11: 63 | AJ11: 0 | AK11: 50 | AL11: 50 | AM11: 50 | AN11: 50 | AO11: 0 | AP11: 0 | AR11: 4 | AS11: 3 | AT11: 3 | AU11: 3 | AV11: 4 | AW11: 4 | AX11: 3 | AY11: 3 | AZ11: 0 | BA11: 0 | BB11: 4 | BC11: 4 | BD11: 4 | BE11: 3 | BF11: 3 | BG11: 4 | BH11: 3 | BI11: 3 | BJ11: 4 | BK11: 4 | BL11: 0 | BM11: 3 | BN11: 3 | BO11: 0 | BP11: 3 | BQ11: 8 | BR11: 16 | BS11: 6 | BT11: 12 | BU11: 8 | BV11: 12 | BW11: 0 | BX11: 4 | BY11: 3 | BZ11: 3 | CA11: 0 | CB11: 0 | CC11: 0 | CE11: 0 | CF11: 0 | CG11: 0 | CH11: 0 | CI11: 0 | CJ11: 0 | CK11: 0 | CL11: 0 | CM11: 0 | CN11: 0 | CO11: 0 | CP11: 0 | CQ11: 0 | CR11: 0 | CS11: 0 | CT11: 0 | CU11: 0 | CV11: 0 | CW11: 0 | CX11: 0 | CY11: 0 | CZ11: 0 | DA11: 0 | DB11: 0 | DC11: 0 | DD11: 0 | DE11: 0 | DF11: 0 | DG11: 0 | DH11: 0 | DI11: 0 | DJ11: 0 | DK11: 0 | DL11: 0 | DM11: 0 | DN11: 0 | DO11: 0 | DP11: 0
A12: New Jersey Institute Of Technology | B12: Newark | C12: NJ | D12: 2513 | E12: 50 | F12: 0 | G12: 50 | H12: 50 | I12: 0 | J12: 0 | K12: 50 | L12: 50 | M12: 0 | N12: 0 | O12: 0 | P12: 0 | Q12: 0 | R12: 0 | S12: 0 | T12: 0 | U12: 0 | V12: 0 | W12: 0 | X12: 0 | Y12: 0 | Z12: 0 | AA12: 0 | AB12: 0 | AC12: 0 | AD12: 50 | AE12: 0 | AF12: 50 | AG12: 0 | AH12: 50 | AI12: 0 | AJ12: 0 | AK12: 0 | AL12: 0 | AM12: 0 | AN12: 0 | AO12: 0 | AP12: 0 | AR12: 3 | AS12: 0 | AT12: 3 | AU12: 3 | AV12: 0 | AW12: 0 | AX12: 3 | AY12: 3 | AZ12: 0 | BA12: 0 | BB12: 0 | BC12: 0 | BD12: 0 | BE12: 0 | BF12: 0 | BG12: 0 | BH12: 0 | BI12: 0 | BJ12: 0 | BK12: 0 | BL12: 0 | BM12: 0 | BN12: 0 | BO12: 0 | BP12: 0 | BQ12: 3 | BR12: 0 | BS12: 3 | BT12: 0 | BU12: 3 | BV12: 0 | BW12: 0 | BX12: 0 | BY12: 0 | BZ12: 0 | CA12: 0 | CB12: 0 | CC12: 0 | CE12: 0 | CF12: 0 | CG12: 0 | CH12: 0 | CI12: 0 | CJ12: 0 | CK12: 0 | CL12: 0 | CM12: 0 | CN12: 0 | CO12: 0 | CP12: 0 | CQ12: 0 | CR12: 0 | CS12: 0 | CT12: 0 | CU12: 0 | CV12: 0 | CW12: 0 | CX12: 0 | CY12: 0 | CZ12: 0 | DA12: 0 | DB12: 0 | DC12: 0 | DD12: 0 | DE12: 0 | DF12: 0 | DG12: 0 | DH12: 0 | DI12: 0 | DJ12: 0 | DK12: 0 | DL12: 0 | DM12: 0 | DN12: 0 | DO12: 0 | DP12: 0
A13: Purdue University - West Lafayette | B13: West Lafayette | C13: IN | D13: 1631 | E13: 50 | F13: 50 | G13: 50 | H13: 50 | I13: 50 | J13: 50 | K13: 50 | L13: 50 | M13: 50 | N13: 50 | O13: 50 | P13: 50 | Q13: 50 | R13: 50 | S13: 50 | T13: 50 | U13: 50 | V13: 50 | W13: 55/70 | X13: 50/65/70 | Y13: 50 | Z13: 50/60 | AA13: 50 | AB13: 50 | AC13: 50 | AD13: 50 | AE13: 59/64/69 | AF13: 50 | AG13: 59/64/69 | AH13: 0 | AI13: 50 | AJ13: 59/64/69 | AK13: 50 | AL13: 50 | AM13: 45 | AN13: 50 | AO13: 50 | AP13: 59/64/69 | AR13: 3 | AS13: 3 | AT13: 3 | AU13: 3 | AV13: 3 | AW13: 3 | AX13: 3 | AY13: 3 | AZ13: 3 | BA13: 3 | BB13: 3 | BC13: 3 | BD13: 3 | BE13: 3 | BF13: 3 | BG13: 3 | BH13: 3 | BI13: 3 | BJ13: 4/8 | BK13: 3/4/8 | BL13: 3 | BM13: 3/4 | BN13: 3 | BO13: 3 | BP13: 3 | BQ13: 3 | BR13: 6/9/12 | BS13: 3 | BT13: 6/9/12 | BU13: 0 | BV13: 3 | BW13: 6/9/12 | BX13: 3 | BY13: 3 | BZ13: 2 | CA13: 3 | CB13: 3 | CC13: 6/9/12 | CE13: 0 | CF13: UND 1XXXXX | CG13: POL 10100 | CH13: HIST 15100 | CI13: HIST 15200 | CJ13: SOC 10000 | CK13: UND 1XXXXX | CL13: HIST 10300 | CM13: HIST 10400 | CN13: UND 1XXXXX | CO13: UND 1XXXXX | CP13: ENGL 25000 | CQ13: ENGL 23100 | CR13: ENGL 1XXXX | CS13: HDFS 21000 | CT13: EDPS 49000 | CU13: PSY 12000 | CV13: ECON 21000 | CW13: ECON 21000 | CX13: BIOL 11000/BIOL 11000, BIOL 11100 | CY13: CHM 11100/CHM 11500/CHM 11500, CHM 11600 | CZ13: SCI 1XXXX | DA13: MA 16010/MA16500 | DB13: MA 15300 | DC13: MA 1XXXX | DD13: MA 15800 | DE13: FR 10100 | DF13: FR 10100, FR 10200, FR 20100, FR 20200 | DG13: GER 10100 | DH13: GR 10100, GR 10200, GR 20100, GR 20200 | DI13: 0 | DJ13: SPAN 10100 | DK13: SPAN 10100, SPAN 10200, SPAN 20100, SPAN 20200 | DL13: CNIT 2XXXX | DM13: MGMT 2XXXX | DN13: MGMT 1XXXX | DO13: MGMT 1XXXX | DP13: SPAN 10100
A14: Purdue University - Northwest | B14: Hammond | C14: IN | D14: 1638 | E14: No Score Given | F14: 50 | G14: 50 | H14: 50 | I14: 45 | J14: No Score Given | K14: 50 | L14: 50 | M14: 49 | N14: No Score Given | O14: 50 | P14: 50 | Q14: 50 | R14: 45 | S14: 45 | T14: 47 | U14: 50 | V14: 50 | W14: 48 | X14: 55/55/70 | Y14: No Score Given | Z14: 50/55/60 | AA14: 50 | AB14: No Score Given | AC14: 50 | AD14: 50 | AE14: 0 | AF14: 50 | AG14: 0 | AH14: 50 | AI14: 0 | AJ14: 50 | AK14: 50 | AL14: 50 | AM14: 50 | AN14: 50 | AO14: 50 | AP14: 50 | AR14: No Credit Given | AS14: 3 | AT14: 3 | AU14: 3 | AV14: 3 | AW14: No Credit Given | AX14: 3 | AY14: 3 | AZ14: 3 | BA14: No Credit Given | BB14: 6 | BC14: 3 | BD14: 3 | BE14: 3 | BF14: 3 | BG14: 3 | BH14: 3 | BI14: 3 | BJ14: 8 | BK14: 3/4/8 | BL14: No Credit Given | BM14: 3/4/5 | BN14: 3 | BO14: No Credit Given | BP14: 3 | BQ14: 3 | BR14: 0 | BS14: 3 | BT14: 0 | BU14: 3 | BV14: 0 | BW14: 3 | BX14: 3 | BY14: 3 | BZ14: 3 | CA14: 3 | CB14: 3 | CC14: 3 | CE14: 0 | CF14: No Course Given | CG14: POL 10100 | CH14: HIST 15100 | CI14: HIST 15200 | CJ14: SOC 10000 | CK14: No Course Given | CL14: HIST 10300 | CM14: HIST 10400 | CN14: ENGL 10400 | CO14: No Course Given | CP14: ENGL 35000, ENGL 35100 | CQ14: ENGL 23100 | CR14: ENGL 1XXXX (UND) | CS14: HDFS 21000 | CT14: EDPS 22000 | CU14: PSY 12000 | CV14: ECON 25200 | CW14: ECON 25100 | CX14: BIOL 11000, BIOL 11100 | CY14: CHM 11100/CHM 11500/CHM 11500, CHM 11600 | CZ14: No Course Given | DA14: MA 15910/MA 16019/MA 16300 | DB14: MA 15200 or MA 15300 | DC14: No Course Given | DD14: MA 15900 | DE14: FR 10100 | DF14: 0 | DG14: GER 10100 | DH14: 0 | DI14: SPAN 10100 | DJ14: 0 | DK14: ACC 20000 | DL14: CIS 20400 | DM14: BUSM 35400 | DN14: OBHR 22100 | DO14: MKG 22400 | DP14: SPAN 20120
A15: Purdue University - North Central | B15: Westville | C15: IN | D15: 1640 | E15: 50 | F15: 50 | G15: 50 | H15: 50 | I15: 45 | J15: 50 | K15: 50 | L15: 50 | M15: 49 | N15: 49 | O15: 50 | P15: 50 | Q15: 50 | R15: 45 | S15: 45 | T15: 47 | U15: 50 | V15: 50 | W15: 48 | X15: 55 | Y15: 50 | Z15: 50 | AA15: 50 | AB15: 50 | AC15: 50 | AD15: 50 | AE15: 64 | AF15: 50 | AG15: 64 | AH15: 50 | AI15: 64 | AJ15: 50 | AK15: 50 | AL15: 50 | AM15: 50 | AN15: 50 | AO15: 0 | AP15: 0 | AR15: 3 | AS15: 3 | AT15: 3 | AU15: 3 | AV15: 3 | AW15: 3 | AX15: 3 | AY15: 3 | AZ15: 3 | BA15: 3 | BB15: 6 | BC15: 3 | BD15: 3 | BE15: 3 | BF15: 3 | BG15: 3 | BH15: 3 | BI15: 3 | BJ15: 8 | BK15: 3 | BL15: 3 | BM15: 3 | BN15: 3 | BO15: 3 | BP15: 3 | BQ15: 3 | BR15: 9 | BS15: 3 | BT15: 9 | BU15: 3 | BV15: 9 | BW15: 3 | BX15: 3 | BY15: 3 | BZ15: 3 | CA15: 3 | CB15: 0 | CC15: 0 | CE15: 0 | CF15: 0 | CG15: 0 | CH15: 0 | CI15: 0 | CJ15: 0 | CK15: 0 | CL15: 0 | CM15: 0 | CN15: 0 | CO15: 0 | CP15: 0 | CQ15: 0 | CR15: 0 | CS15: 0 | CT15: 0 | CU15: 0 | CV15: 0 | CW15: 0 | CX15: 0 | CY15: 0 | CZ15: 0 | DA15: 0 | DB15: 0 | DC15: 0 | DD15: 0 | DE15: 0 | DF15: 0 | DG15: 0 | DH15: 0 | DI15: 0 | DJ15: 0 | DK15: 0 | DL15: 0 | DM15: 0 | DN15: 0 | DO15: 0 | DP15: 0
A16: New York University | B16: New York | C16: NY | D16: 2595 | E16: 0 | F16: 0 | G16: 0 | H16: 0 | I16: 0 | J16: 0 | K16: 0 | L16: 0 | M16: 0 | N16: 0 | O16: 0 | P16: 0 | Q16: 0 | R16: 0 | S16: 0 | T16: 0 | U16: 0 | V16: 0 | W16: 0 | X16: 0 | Y16: 0 | Z16: 0 | AA16: 0 | AB16: 0 | AC16: 0 | AD16: 0 | AE16: 0 | AF16: 0 | AG16: 0 | AH16: 0 | AI16: 0 | AJ16: 0 | AK16: 0 | AL16: 0 | AM16: 0 | AN16: 0 | AO16: 0 | AP16: 0 | AR16: 0 | AS16: 0 | AT16: 0 | AU16: 0 | AV16: 0 | AW16: 0 | AX16: 0 | AY16: 0 | AZ16: 0 | BA16: 0 | BB16: 0 | BC16: 0 | BD16: 0 | BE16: 0 | BF16: 0 | BG16: 0 | BH16: 0 | BI16: 0 | BJ16: 0 | BK16: 0 | BL16: 0 | BM16: 0 | BN16: 0 | BO16: 0 | BP16: 0 | BQ16: 0 | BR16: 0 | BS16: 0 | BT16: 0 | BU16: 0 | BV16: 0 | BW16: 0 | BX16: 0 | BY16: 0 | BZ16: 0 | CA16: 0 | CB16: 0 | CC16: 0 | CE16: 0 | CF16: 0 | CG16: 0 | CH16: 0 | CI16: 0 | CJ16: 0 | CK16: 0 | CL16: 0 | CM16: 0 | CN16: 0 | CO16: 0 | CP16: 0 | CQ16: 0 | CR16: 0 | CS16: 0 | CT16: 0 | CU16: 0 | CV16: 0 | CW16: 0 | CX16: 0 | CY16: 0 | CZ16: 0 | DA16: 0 | DB16: 0 | DC16: 0 | DD16: 0 | DE16: 0 | DF16: 0 | DG16: 0 | DH16: 0 | DI16: 0 | DJ16: 0 | DK16: 0 | DL16: 0 | DM16: 0 | DN16: 0 | DO16: 0 | DP16: 0
A17: Northwestern University - Chicago | B17: Chicago | C17: IL | D17: 1578 | E17: 50 | F17: 50 | G17: 50 | H17: 50 | I17: 50 | J17: 50 | K17: 50 | L17: 50 | M17: 50 | N17: 50 | O17: 50 | P17: 50 | Q17: 50 | R17: 50 | S17: 50 | T17: 50 | U17: 50 | V17: 50 | W17: 50 | X17: 50 | Y17: 50 | Z17: 50 | AA17: 50 | AB17: 50 | AC17: 50 | AD17: 50 | AE17: 63 | AF17: 50 | AG17: 63 | AH17: 50 | AI17: 63 | AJ17: 50 | AK17: 50 | AL17: 50 | AM17: 50 | AN17: 50 | AO17: 0 | AP17: 0 | AR17: 2 | AS17: 1 | AT17: 1 | AU17: 1 | AV17: 1 | AW17: 2 | AX17: 1 | AY17: 1 | AZ17: 2 | BA17: 2 | BB17: 2 | BC17: 2 | BD17: 2 | BE17: 1 | BF17: 1 | BG17: 1 | BH17: 1 | BI17: 1 | BJ17: 2 | BK17: 2 | BL17: 2 | BM17: 1 | BN17: 0 | BO17: 2 | BP17: 1 | BQ17: 2 | BR17: 3 | BS17: 2 | BT17: 3 | BU17: 2 | BV17: 3 | BW17: 1 | BX17: 1 | BY17: 1 | BZ17: 1 | CA17: 1 | CB17: 0 | CC17: 0 | CE17: 0 | CF17: 0 | CG17: 0 | CH17: 0 | CI17: 0 | CJ17: 0 | CK17: 0 | CL17: 0 | CM17: 0 | CN17: 0 | CO17: 0 | CP17: 0 | CQ17: 0 | CR17: 0 | CS17: 0 | CT17: 0 | CU17: 0 | CV17: 0 | CW17: 0 | CX17: 0 | CY17: 0 | CZ17: 0 | DA17: 0 | DB17: 0 | DC17: 0 | DD17: 0 | DE17: 0 | DF17: 0 | DG17: 0 | DH17: 0 | DI17: 0 | DJ17: 0 | DK17: 0 | DL17: 0 | DM17: 0 | DN17: 0 | DO17: 0 | DP17: 0
A18: Ohio Northern University | B18: Ada | C18: OH | D18: 1591 | E18: 0 | F18: 60 | G18: 59 | H18: 59 | I18: 55 | J18: 0 | K18: 52 | L18: 52 | M18: 0 | N18: 0 | O18: 0 | P18: 0 | Q18: 46 | R18: 55 | S18: 0 | T18: 55 | U18: 50 | V18: 50 | W18: 50 | X18: 50 | Y18: 0 | Z18: 50 | AA18: 50 | AB18: 50 | AC18: 50 | AD18: 64 | AE18: 69 | AF18: 59 | AG18: 67 | AH18: 56 | AI18: 68 | AJ18: 0 | AK18: 0 | AL18: 0 | AM18: 0 | AN18: 0 | AO18: 0 | AP18: 0 | AR18: 0 | AS18: 3 | AT18: 3 | AU18: 3 | AV18: 4 | AW18: 0 | AX18: 3 | AY18: 3 | AZ18: 0 | BA18: 0 | BB18: 0 | BC18: 0 | BD18: 4 | BE18: 4 | BF18: 0 | BG18: 3 | BH18: 4 | BI18: 4 | BJ18: 4 | BK18: 3 | BL18: 0 | BM18: 3 | BN18: 3 | BO18: 3 | BP18: 3 | BQ18: 6 | BR18: 12 | BS18: 6 | BT18: 12 | BU18: 6 | BV18: 12 | BW18: 0 | BX18: 0 | BY18: 0 | BZ18: 0 | CA18: 0 | CB18: 0 | CC18: 0 | CE18: 0 | CF18: 0 | CG18: 0 | CH18: 0 | CI18: 0 | CJ18: 0 | CK18: 0 | CL18: 0 | CM18: 0 | CN18: 0 | CO18: 0 | CP18: 0 | CQ18: 0 | CR18: 0 | CS18: 0 | CT18: 0 | CU18: 0 | CV18: 0 | CW18: 0 | CX18: 0 | CY18: 0 | CZ18: 0 | DA18: 0 | DB18: 0 | DC18: 0 | DD18: 0 | DE18: 0 | DF18: 0 | DG18: 0 | DH18: 0 | DI18: 0 | DJ18: 0 | DK18: 0 | DL18: 0 | DM18: 0 | DN18: 0 | DO18: 0 | DP18: 0
A19: Ohio State University | B19: Columbus | C19: OH | D19: 1592 | E19: 55 | F19: 56 | G19: 61 | H19: 57 | I19: 56 | J19: 63 | K19: 55 | L19: 54 | M19: 50 | N19: 50 | O19: 0 | P19: 53 | Q19: 63 | R19: 58 | S19: 62 | T19: 55 | U19: 56 | V19: 57 | W19: 50 | X19: 50 | Y19: 0 | Z19: 64 | AA19: 63 | AB19: 63 | AC19: 61 | AD19: 55 | AE19: 65 | AF19: 52 | AG19: 65 | AH19: 56 | AI19: 63 | AJ19: 0 | AK19: 50 | AL19: 57 | AM19: 50 | AN19: 65 | AO19: 0 | AP19: 0 | AR19: 3 | AS19: 3 | AT19: 3 | AU19: 3 | AV19: 3 | AW19: 3 | AX19: 3 | AY19: 3 | AZ19: 0 | BA19: 0 | BB19: 0 | BC19: 3 | BD19: 3 | BE19: 3 | BF19: 3 | BG19: 3 | BH19: 3 | BI19: 3 | BJ19: 3 | BK19: 3 | BL19: 0 | BM19: 5 | BN19: 4 | BO19: 3 | BP19: 5 | BQ19: 8 | BR19: 12 | BS19: 8 | BT19: 12 | BU19: 8 | BV19: 12 | BW19: 0 | BX19: 3 | BY19: 3 | BZ19: 3 | CA19: 3 | CB19: 0 | CC19: 0 | CE19: 0 | CF19: 0 | CG19: 0 | CH19: 0 | CI19: 0 | CJ19: 0 | CK19: 0 | CL19: 0 | CM19: 0 | CN19: 0 | CO19: 0 | CP19: 0 | CQ19: 0 | CR19: 0 | CS19: 0 | CT19: 0 | CU19: 0 | CV19: 0 | CW19: 0 | CX19: 0 | CY19: 0 | CZ19: 0 | DA19: 0 | DB19: 0 | DC19: 0 | DD19: 0 | DE19: 0 | DF19: 0 | DG19: 0 | DH19: 0 | DI19: 0 | DJ19: 0 | DK19: 0 | DL19: 0 | DM19: 0 | DN19: 0 | DO19: 0 | DP19: 0
A20: Penn State University - DuBois | B20: DuBois | C20: PA | D20: 2795 | E20: 50 | F20: 50 | G20: 0 | H20: 0 | I20: 50 | J20: 50 | K20: 50 | L20: 50 | M20: 0 | N20: 0 | O20: 0 | P20: 0 | Q20: 0 | R20: 50 | S20: 50 | T20: 50 | U20: 50 | V20: 50 | W20: 0 | X20: 0 | Y20: 50 | Z20: 50 | AA20: 50 | AB20: 50 | AC20: 50 | AD20: 50 | AE20: 59 | AF20: 50 | AG20: 60 | AH20: 50 | AI20: 63 | AJ20: 0 | AK20: 50 | AL20: 50 | AM20: 50 | AN20: 50 | AO20: 0 | AP20: 0 | AR20: 3 | AS20: 3 | AT20: 0 | AU20: 0 | AV20: 3 | AW20: 3 | AX20: 3 | AY20: 3 | AZ20: 0 | BA20: 0 | BB20: 0 | BC20: 0 | BD20: 0 | BE20: 3 | BF20: 3 | BG20: 3 | BH20: 3 | BI20: 3 | BJ20: 0 | BK20: 0 | BL20: 3 | BM20: 4 | BN20: 3 | BO20: 3 | BP20: 3 | BQ20: 8 | BR20: 12 | BS20: 8 | BT20: 12 | BU20: 8 | BV20: 12 | BW20: 0 | BX20: 3 | BY20: 3 | BZ20: 3 | CA20: 3 | CB20: 0 | CC20: 0 | CE20: 0 | CF20: 0 | CG20: 0 | CH20: 0 | CI20: 0 | CJ20: 0 | CK20: 0 | CL20: 0 | CM20: 0 | CN20: 0 | CO20: 0 | CP20: 0 | CQ20: 0 | CR20: 0 | CS20: 0 | CT20: 0 | CU20: 0 | CV20: 0 | CW20: 0 | CX20: 0 | CY20: 0 | CZ20: 0 | DA20: 0 | DB20: 0 | DC20: 0 | DD20: 0 | DE20: 0 | DF20: 0 | DG20: 0 | DH20: 0 | DI20: 0 | DJ20: 0 | DK20: 0 | DL20: 0 | DM20: 0 | DN20: 0 | DO20: 0 | DP20: 0
A21: Rutgers University Newark - Arts & Science | B21: Piscataway | C21: NJ | D21: 2512 | E21: 0 | F21: 0 | G21: 0 | H21: 0 | I21: 0 | J21: 0 | K21: 0 | L21: 0 | M21: 0 | N21: 0 | O21: 0 | P21: 0 | Q21: 0 | R21: 0 | S21: 0 | T21: 0 | U21: 0 | V21: 0 | W21: 0 | X21: 0 | Y21: 0 | Z21: 0 | AA21: 0 | AB21: 0 | AC21: 0 | AD21: 0 | AE21: 0 | AF21: 0 | AG21: 0 | AH21: 0 | AI21: 0 | AJ21: 0 | AK21: 0 | AL21: 0 | AM21: 0 | AN21: 0 | AO21: 0 | AP21: 0 | AR21: 0 | AS21: 0 | AT21: 0 | AU21: 0 | AV21: 0 | AW21: 0 | AX21: 0 | AY21: 0 | AZ21: 0 | BA21: 0 | BB21: 0 | BC21: 0 | BD21: 0 | BE21: 0 | BF21: 0 | BG21: 0 | BH21: 0 | BI21: 0 | BJ21: 0 | BK21: 0 | BL21: 0 | BM21: 0 | BN21: 0 | BO21: 0 | BP21: 0 | BQ21: 0 | BR21: 0 | BS21: 0 | BT21: 0 | BU21: 0 | BV21: 0 | BW21: 0 | BX21: 0 | BY21: 0 | BZ21: 0 | CA21: 0 | CB21: 0 | CC21: 0 | CE21: 0 | CF21: 0 | CG21: 0 | CH21: 0 | CI21: 0 | CJ21: 0 | CK21: 0 | CL21: 0 | CM21: 0 | CN21: 0 | CO21: 0 | CP21: 0 | CQ21: 0 | CR21: 0 | CS21: 0 | CT21: 0 | CU21: 0 | CV21: 0 | CW21: 0 | CX21: 0 | CY21: 0 | CZ21: 0 | DA21: 0 | DB21: 0 | DC21: 0 | DD21: 0 | DE21: 0 | DF21: 0 | DG21: 0 | DH21: 0 | DI21: 0 | DJ21: 0 | DK21: 0 | DL21: 0 | DM21: 0 | DN21: 0 | DO21: 0 | DP21: 0
A22: Penn State University - Fayette Eberly Campus | B22: Lemont Furnace | C22: PA | D22: 2691 | E22: 0 | F22: 0 | G22: 0 | H22: 0 | I22: 0 | J22: 0 | K22: 0 | L22: 0 | M22: 0 | N22: 0 | O22: 0 | P22: 0 | Q22: 0 | R22: 0 | S22: 0 | T22: 0 | U22: 0 | V22: 0 | W22: 0 | X22: 0 | Y22: 0 | Z22: 0 | AA22: 0 | AB22: 0 | AC22: 0 | AD22: 0 | AE22: 0 | AF22: 0 | AG22: 0 | AH22: 0 | AI22: 0 | AJ22: 0 | AK22: 0 | AL22: 0 | AM22: 0 | AN22: 0 | AO22: 0 | AP22: 0 | AR22: 3 | AS22: 3 | AT22: 0 | AU22: 0 | AV22: 3 | AW22: 3 | AX22: 3 | AY22: 3 | AZ22: 0 | BA22: 0 | BB22: 0 | BC22: 0 | BD22: 0 | BE22: 3 | BF22: 3 | BG22: 3 | BH22: 3 | BI22: 3 | BJ22: 0 | BK22: 0 | BL22: 3 | BM22: 4 | BN22: 3 | BO22: 3 | BP22: 3 | BQ22: 8 | BR22: 12 | BS22: 8 | BT22: 12 | BU22: 8 | BV22: 12 | BW22: 0 | BX22: 3 | BY22: 3 | BZ22: 3 | CA22: 3 | CB22: 0 | CC22: 0 | CE22: 0 | CF22: 0 | CG22: 0 | CH22: 0 | CI22: 0 | CJ22: 0 | CK22: 0 | CL22: 0 | CM22: 0 | CN22: 0 | CO22: 0 | CP22: 0 | CQ22: 0 | CR22: 0 | CS22: 0 | CT22: 0 | CU22: 0 | CV22: 0 | CW22: 0 | CX22: 0 | CY22: 0 | CZ22: 0 | DA22: 0 | DB22: 0 | DC22: 0 | DD22: 0 | DE22: 0 | DF22: 0 | DG22: 0 | DH22: 0 | DI22: 0 | DJ22: 0 | DK22: 0 | DL22: 0 | DM22: 0 | DN22: 0 | DO22: 0 | DP22: 0
A23: Penn State University - Great Valley | B23: Malvern | C23: PA | D23: 2723 | E23: 0 | F23: 0 | G23: 0 | H23: 0 | I23: 0 | J23: 0 | K23: 0 | L23: 0 | M23: 0 | N23: 0 | O23: 0 | P23: 0 | Q23: 0 | R23: 0 | S23: 0 | T23: 0 | U23: 0 | V23: 0 | W23: 0 | X23: 0 | Y23: 0 | Z23: 0 | AA23: 0 | AB23: 0 | AC23: 0 | AD23: 0 | AE23: 0 | AF23: 0 | AG23: 0 | AH23: 0 | AI23: 0 | AJ23: 0 | AK23: 0 | AL23: 0 | AM23: 0 | AN23: 0 | AO23: 0 | AP23: 0 | AR23: 3 | AS23: 3 | AT23: 0 | AU23: 0 | AV23: 3 | AW23: 3 | AX23: 3 | AY23: 3 | AZ23: 0 | BA23: 0 | BB23: 0 | BC23: 0 | BD23: 0 | BE23: 3 | BF23: 3 | BG23: 3 | BH23: 3 | BI23: 3 | BJ23: 0 | BK23: 0 | BL23: 3 | BM23: 4 | BN23: 3 | BO23: 3 | BP23: 3 | BQ23: 8 | BR23: 12 | BS23: 8 | BT23: 12 | BU23: 8 | BV23: 12 | BW23: 0 | BX23: 3 | BY23: 3 | BZ23: 3 | CA23: 3 | CB23: 0 | CC23: 0 | CE23: 0 | CF23: 0 | CG23: 0 | CH23: 0 | CI23: 0 | CJ23: 0 | CK23: 0 | CL23: 0 | CM23: 0 | CN23: 0 | CO23: 0 | CP23: 0 | CQ23: 0 | CR23: 0 | CS23: 0 | CT23: 0 | CU23: 0 | CV23: 0 | CW23: 0 | CX23: 0 | CY23: 0 | CZ23: 0 | DA23: 0 | DB23: 0 | DC23: 0 | DD23: 0 | DE23: 0 | DF23: 0 | DG23: 0 | DH23: 0 | DI23: 0 | DJ23: 0 | DK23: 0 | DL23: 0 | DM23: 0 | DN23: 0 | DO23: 0 | DP23: 0
A24: Penn State University - Greater Alleghany | B24: Mckeesport | C24: PA | D24: 2707 | E24: 50 | F24: 50 | G24: 0 | H24: 0 | I24: 50 | J24: 50 | K24: 50 | L24: 50 | M24: 0 | N24: 0 | O24: 0 | P24: 0 | Q24: 0 | R24: 50 | S24: 50 | T24: 50 | U24: 50 | V24: 50 | W24: 50 | X24: 50 | Y24: 50 | Z24: 50 | AA24: 50 | AB24: 50 | AC24: 50 | AD24: 50 | AE24: 59 | AF24: 50 | AG24: 60 | AH24: 50 | AI24: 63 | AJ24: 50 | AK24: 50 | AL24: 50 | AM24: 50 | AN24: 50 | AO24: 0 | AP24: 0 | AR24: 3 | AS24: 3 | AT24: 0 | AU24: 0 | AV24: 3 | AW24: 6 | AX24: 3 | AY24: 3 | AZ24: 0 | BA24: 0 | BB24: 0 | BC24: 0 | BD24: 0 | BE24: 3 | BF24: 3 | BG24: 3 | BH24: 3 | BI24: 3 | BJ24: 6 | BK24: 6 | BL24: 3 | BM24: 4 | BN24: 3 | BO24: 3 | BP24: 3 | BQ24: 8 | BR24: 12 | BS24: 8 | BT24: 12 | BU24: 8 | BV24: 12 | BW24: 0 | BX24: 3 | BY24: 3 | BZ24: 3 | CA24: 3 | CB24: 0 | CC24: 0 | CE24: 0 | CF24: 0 | CG24: 0 | CH24: 0 | CI24: 0 | CJ24: 0 | CK24: 0 | CL24: 0 | CM24: 0 | CN24: 0 | CO24: 0 | CP24: 0 | CQ24: 0 | CR24: 0 | CS24: 0 | CT24: 0 | CU24: 0 | CV24: 0 | CW24: 0 | CX24: 0 | CY24: 0 | CZ24: 0 | DA24: 0 | DB24: 0 | DC24: 0 | DD24: 0 | DE24: 0 | DF24: 0 | DG24: 0 | DH24: 0 | DI24: 0 | DJ24: 0 | DK24: 0 | DL24: 0 | DM24: 0 | DN24: 0 | DO24: 0 | DP24: 0
A25: Penn State University - Harrisburg | B25: Middletown | C25: PA | D25: 2708 | E25: 50 | F25: 50 | G25: 0 | H25: 0 | I25: 50 | J25: 50 | K25: 50 | L25: 50 | M25: 0 | N25: 0 | O25: 0 | P25: 0 | Q25: 0 | R25: 50 | S25: 50 | T25: 50 | U25: 50 | V25: 50 | W25: 0 | X25: 0 | Y25: 50 | Z25: 50 | AA25: 50 | AB25: 50 | AC25: 50 | AD25: 50 | AE25: 62 | AF25: 50 | AG25: 63 | AH25: 50 | AI25: 63 | AJ25: 0 | AK25: 50 | AL25: 50 | AM25: 50 | AN25: 50 | AO25: 0 | AP25: 0 | AR25: 3 | AS25: 3 | AT25: 0 | AU25: 0 | AV25: 3 | AW25: 3 | AX25: 3 | AY25: 3 | AZ25: 0 | BA25: 0 | BB25: 0 | BC25: 0 | BD25: 0 | BE25: 3 | BF25: 3 | BG25: 3 | BH25: 3 | BI25: 3 | BJ25: 0 | BK25: 0 | BL25: 3 | BM25: 4 | BN25: 3 | BO25: 3 | BP25: 3 | BQ25: 4 | BR25: 12 | BS25: 4 | BT25: 12 | BU25: 4 | BV25: 12 | BW25: 0 | BX25: 3 | BY25: 3 | BZ25: 3 | CA25: 3 | CB25: 0 | CC25: 0 | CE25: 0 | CF25: 0 | CG25: 0 | CH25: 0 | CI25: 0 | CJ25: 0 | CK25: 0 | CL25: 0 | CM25: 0 | CN25: 0 | CO25: 0 | CP25: 0 | CQ25: 0 | CR25: 0 | CS25: 0 | CT25: 0 | CU25: 0 | CV25: 0 | CW25: 0 | CX25: 0 | CY25: 0 | CZ25: 0 | DA25: 0 | DB25: 0 | DC25: 0 | DD25: 0 | DE25: 0 | DF25: 0 | DG25: 0 | DH25: 0 | DI25: 0 | DJ25: 0 | DK25: 0 | DL25: 0 | DM25: 0 | DN25: 0 | DO25: 0 | DP25: 0
A26: Penn State University - Mont Alto | B26: Monto Alto | C26: PA | D26: 2710 | E26: 50 | F26: 50 | G26: 0 | H26: 0 | I26: 50 | J26: 0 | K26: 50 | L26: 50 | M26: 0 | N26: 0 | O26: 0 | P26: 0 | Q26: 0 | R26: 50 | S26: 50 | T26: 50 | U26: 50 | V26: 50 | W26: 0 | X26: 0 | Y26: 50 | Z26: 50 | AA26: 50 | AB26: 50 | AC26: 50 | AD26: 50 | AE26: 62 | AF26: 50 | AG26: 63 | AH26: 50 | AI26: 63 | AJ26: 0 | AK26: 50 | AL26: 50 | AM26: 50 | AN26: 50 | AO26: 0 | AP26: 0 | AR26: 3 | AS26: 3 | AT26: 0 | AU26: 0 | AV26: 3 | AW26: 0 | AX26: 3 | AY26: 3 | AZ26: 0 | BA26: 0 | BB26: 0 | BC26: 0 | BD26: 0 | BE26: 3 | BF26: 3 | BG26: 3 | BH26: 3 | BI26: 3 | BJ26: 0 | BK26: 0 | BL26: 3 | BM26: 4 | BN26: 3 | BO26: 3 | BP26: 3 | BQ26: 4 | BR26: 12 | BS26: 4 | BT26: 12 | BU26: 4 | BV26: 12 | BW26: 0 | BX26: 3 | BY26: 3 | BZ26: 3 | CA26: 3 | CB26: 0 | CC26: 0 | CE26: 0 | CF26: 0 | CG26: 0 | CH26: 0 | CI26: 0 | CJ26: 0 | CK26: 0 | CL26: 0 | CM26: 0 | CN26: 0 | CO26: 0 | CP26: 0 | CQ26: 0 | CR26: 0 | CS26: 0 | CT26: 0 | CU26: 0 | CV26: 0 | CW26: 0 | CX26: 0 | CY26: 0 | CZ26: 0 | DA26: 0 | DB26: 0 | DC26: 0 | DD26: 0 | DE26: 0 | DF26: 0 | DG26: 0 | DH26: 0 | DI26: 0 | DJ26: 0 | DK26: 0 | DL26: 0 | DM26: 0 | DN26: 0 | DO26: 0 | DP26: 0
... A33: Rutgers University College of Nursing | B33: Newark | C33: NJ | D33: 2789 | E33: 0 | F33: 0 | G33: 0 | H33: 0 | I33: 0 | J33: 0 | K33: 0 | L33: 0 | M33: 0 | N33: 0 | O33: 0 | P33: 0 | Q33: 0 | R33: 50 | S33: 0 | T33: 0 | U33: 0 | V33: 0 | W33: 0 | X33: 0 | Y33: 0 | Z33: 0 | AA33: 0 | AB33: 0 | AC33: 0 | AD33: 0 | AE33: 0 | AF33: 0 | AG33: 0 | AH33: 0 | AI33: 0 | AJ33: 0 | AK33: 0 | AL33: 0 | AM33: 0 | AN33: 0 | AO33: 0 | AP33: 0 | AR33: 0 | AS33: 0 | AT33: 0 | AU33: 0 | AV33: 0 | AW33: 0 | AX33: 0 | AY33: 0 | AZ33: 0 | BA33: 0 | BB33: 0 | BC33: 0 | BD33: 0 | BE33: 3 | BF33: 0 | BG33: 0 | BH33: 0 | BI33: 0 | BJ33: 0 | BK33: 0 | BL33: 0 | BM33: 0 | BN33: 0 | BO33: 0 | BP33: 0 | BQ33: 0 | BR33: 0 | BS33: 0 | BT33: 0 | BU33: 0 | BV33: 0 | BW33: 0 | BX33: 0 | BY33: 0 | BZ33: 0 | CA33: 0 | CB33: 0 | CC33: 0 | CE33: 0 | CF33: 0 | CG33: 0 | CH33: 0 | CI33: 0 | CJ33: 0 | CK33: 0 | CL33: 0 | CM33: 0 | CN33: 0 | CO33: 0 | CP33: 0 | CQ33: 0 | CR33: 0 | CS33: 0 | CT33: 0 | CU33: 0 | CV33: 0 | CW33: 0 | CX33: 0 | CY33: 0 | CZ33: 0 | DA33: 0 | DB33: 0 | DC33: 0 | DD33: 0 | DE33: 0 | DF33: 0 | DG33: 0 | DH33: 0 | DI33: 0 | DJ33: 0 | DK33: 0 | DL33: 0 | DM33: 0 | DN33: 0 | DO33: 0 | DP33: 0
A34: Purdue University Global | B34: Chicago | C34: IL | D34: 8633 | E34: 50 | F34: 50 | G34: 50 | H34: 50 | I34: 50 | J34: 50 | K34: 50 | L34: 50 | M34: 50 | N34: 50 | O34: 50 | P34: 50 | Q34: 50 | R34: 50 | S34: 50 | T34: 50 | U34: 50 | V34: 50 | W34: 50 | X34: 50 | Y34: 50 | Z34: 50 | AA34: 50 | AB34: 50 | AC34: 50 | AD34: 50 | AE34: 59 | AF34: 50 | AG34: 60 | AH34: 50 | AI34: 65 | AJ34: 50 | AK34: 50 | AL34: 50 | AM34: 50 | AN34: 50 | AO34: 50 | AP34: 65 | AR34: 3 | AS34: 3.3 | AT34: 3 | AU34: 3 | AV34: 3.3 | AW34: 6 | AX34: 3 | AY34: 3 | AZ34: 6.6 | BA34: 3.3 | BB34: 3 | BC34: 3 | BD34: 3 | BE34: 3 | BF34: 3 | BG34: 3.3 | BH34: 3.3 | BI34: 3.3 | BJ34: 6 | BK34: 6 | BL34: 6 | BM34: 4 | BN34: 3.3 | BO34: 6 | BP34: 3 | BQ34: 6 | BR34: 9 | BS34: 6 | BT34: 9 | BU34: 6 | BV34: 12 | BW34: 3.3 | BX34: 3 | BY34: 3 | BZ34: 3.3 | CA34: 3.3 | CB34: 6 | CC34: 12 | CE34: 0 | CF34: HU 1XX | CG34: SS236 | CH34: SS 1XX | CI34: SS 1XX | CJ34: SS144 | CK34: SS 1XX | CL34: SS 1XX | CM34: SS 1XX | CN34: CM107 + CM220 | CO34: CM107 | CP34: HU 1XX | CQ34: HU 1XX | CR34: HU 1XX | CS34: SS 1XX | CT34: SS 1XX | CU34: PS124 | CV34: BU204 | CW34: BU224 | CX34: SC235 + LSC 1XX | CY34: SC156 + CHM 1XX | CZ34: SC 1XX | DA34: MM 1XX | DB34: MM212 | DC34: MM150 + MM 1XX | DD34: MM 1XX | DE34: HU 1XX | DF34: HU 1XX | DG34: HU 1XX | DH34: HU 1XX | DI34: HU 1XX | DJ34: HU 1XX | DK34: AC114 | DL34: IT 1XX | DM34: LS 1XX | DN34: MT140 | DO34: MT219 | DP34: HU 1XX
A35: Rutgers University College of Engineering | B35: Piscataway | C35: NJ | D35: 2838 | E35: 0 | F35: 0 | G35: 0 | H35: 0 | I35: 0 | J35: 0 | K35: 0 | L35: 0 | M35: 0 | N35: 0 | O35: 0 | P35: 0 | Q35: 0 | R35: 0 | S35: 0 | T35: 0 | U35: 0 | V35: 0 | W35: 0 | X35: 0 | Y35: 0 | Z35: 0 | AA35: 0 | AB35: 0 | AC35: 0 | AD35: 0 | AE35: 0 | AF35: 0 | AG35: 0 | AH35: 0 | AI35: 0 | AJ35: 0 | AK35: 0 | AL35: 0 | AM35: 0 | AN35: 0 | AO35: 0 | AP35: 0 | AR35: 0 | AS35: 0 | AT35: 0 | AU35: 0 | AV35: 0 | AW35: 0 | AX35: 0 | AY35: 0 | AZ35: 0 | BA35: 0 | BB35: 0 | BC35: 0 | BD35: 0 | BE35: 0 | BF35: 0 | BG35: 0 | BH35: 0 | BI35: 0 | BJ35: 0 | BK35: 0 | BL35: 0 | BM35: 0 | BN35: 0 | BO35: 0 | BP35: 0 | BQ35: 0 | BR35: 0 | BS35: 0 | BT35: 0 | BU35: 0 | BV35: 0 | BW35: 0 | BX35: 0 | BY35: 0 | BZ35: 0 | CA35: 0 | CB35: 0 | CC35: 0 | CE35: 0 | CF35: 0 | CG35: 0 | CH35: 0 | CI35: 0 | CJ35: 0 | CK35: 0 | CL35: 0 | CM35: 0 | CN35: 0 | CO35: 0 | CP35: 0 | CQ35: 0 | CR35: 0 | CS35: 0 | CT35: 0 | CU35: 0 | CV35: 0 | CW35: 0 | CX35: 0 | CY35: 0 | CZ35: 0 | DA35: 0 | DB35: 0 | DC35: 0 | DD35: 0 | DE35: 0 | DF35: 0 | DG35: 0 | DH35: 0 | DI35: 0 | DJ35: 0 | DK35: 0 | DL35: 0 | DM35: 0 | DN35: 0 | DO35: 0 | DP35: 0
A36: Salisbury University | B36: Salisbury | C36: MD | D36: 5403 | E36: 50 | F36: 50 | G36: 67 | H36: 67 | I36: 50 | J36: 67 | K36: 67 | L36: 67 | M36: 0 | N36: 67 | O36: 67 | P36: 0 | Q36: 67 | R36: 67 | S36: 50 | T36: 50 | U36: 50 | V36: 50 | W36: 50 | X36: 50 | Y36: 50 | Z36: 50 | AA36: 50 | AB36: 50 | AC36: 61 | AD36: 50 | AE36: 62 | AF36: 50 | AG36: 63 | AH36: 50 | AI36: 66 | AJ36: 60 | AK36: 50 | AL36: 67 | AM36: 50 | AN36: 50 | AO36: 0 | AP36: 0 | AR36: 4 | AS36: 4 | AT36: 4 | AU36: 4 | AV36: 3 | AW36: 4 | AX36: 4 | AY36: 4 | AZ36: 0 | BA36: 4 | BB36: 4 | BC36: 0 | BD36: 4 | BE36: 4 | BF36: 3 | BG36: 4 | BH36: 3 | BI36: 3 | BJ36: 4 | BK36: 4 | BL36: 3 | BM36: 3 | BN36: 3 | BO36: 3 | BP36: 3 | BQ36: 4 | BR36: 8 | BS36: 4 | BT36: 8 | BU36: 4 | BV36: 8 | BW36: 3 | BX36: 4 | BY36: 4 | BZ36: 3 | CA36: 3 | CB36: 0 | CC36: 0 | CE36: 0 | CF36: 0 | CG36: 0 | CH36: 0 | CI36: 0 | CJ36: 0 | CK36: 0 | CL36: 0 | CM36: 0 | CN36: 0 | CO36: 0 | CP36: 0 | CQ36: 0 | CR36: 0 | CS36: 0 | CT36: 0 | CU36: 0 | CV36: 0 | CW36: 0 | CX36: 0 | CY36: 0 | CZ36: 0 | DA36: 0 | DB36: 0 | DC36: 0 | DD36: 0 | DE36: 0 | DF36: 0 | DG36: 0 | DH36: 0 | DI36: 0 | DJ36: 0 | DK36: 0 | DL36: 0 | DM36: 0 | DN36: 0 | DO36: 0 | DP36: 0
A37: Rutgers University College of Pharmacy | B37: Piscataway | C37: NJ | D37: 2839 | E37: 0 | F37: 0 | G37: 0 | H37: 0 | I37: 0 | J37: 0 | K37: 0 | L37: 0 | M37: 0 | N37: 0 | O37: 0 | P37: 0 | Q37: 0 | R37: 0 | S37: 0 | T37: 0 | U37: 0 | V37: 0 | W37: 0 | X37: 0 | Y37: 0 | Z37: 0 | AA37: 0 | AB37: 0 | AC37: 0 | AD37: 0 | AE37: 0 | AF37: 0 | AG37: 0 | AH37: 0 | AI37: 0 | AJ37: 0 | AK37: 0 | AL37: 0 | AM37: 0 | AN37: 0 | AO37: 0 | AP37: 0 | AR37: 0 | AS37: 0 | AT37: 0 | AU37: 0 | AV37: 0 | AW37: 0 | AX37: 0 | AY37: 0 | AZ37: 0 | BA37: 0 | BB37: 0 | BC37: 0 | BD37: 0 | BE37: 0 | BF37: 0 | BG37: 0 | BH37: 0 | BI37: 0 | BJ37: 0 | BK37: 0 | BL37: 0 | BM37: 0 | BN37: 0 | BO37: 0 | BP37: 0 | BQ37: 0 | BR37: 0 | BS37: 0 | BT37: 0 | BU37: 0 | BV37: 0 | BW37: 0 | BX37: 0 | BY37: 0 | BZ37: 0 | CA37: 0 | CB37: 0 | CC37: 0 | CE37: 0 | CF37: 0 | CG37: 0 | CH37: 0 | CI37: 0 | CJ37: 0 | CK37: 0 | CL37: 0 | CM37: 0 | CN37: 0 | CO37: 0 | CP37: 0 | CQ37: 0 | CR37: 0 | CS37: 0 | CT37: 0 | CU37: 0 | CV37: 0 | CW37: 0 | CX37: 0 | CY37: 0 | CZ37: 0 | DA37: 0 | DB37: 0 | DC37: 0 | DD37: 0 | DE37: 0 | DF37: 0 | DG37: 0 | DH37: 0 | DI37: 0 | DJ37: 0 | DK37: 0 | DL37: 0 | DM37: 0 | DN37: 0 | DO37: 0 | DP37: 0
A38: SUNY at Farmingdale | B38: Farmingdale | C38: NY | D38: 2526 | E38: 0 | F38: 50 | G38: 50 | H38: 50 | I38: 59 | J38: 50 | K38: 50 | L38: 50 | M38: 0 | N38: 0 | O38: 50 | P38: 50 | Q38: 50 | R38: 50 | S38: 50 | T38: 50 | U38: 50 | V38: 50 | W38: 50 | X38: 47 | Y38: 0 | Z38: 50 | AA38: 50 | AB38: 50 | AC38: 50 | AD38: 50 | AE38: 66 | AF38: 50 | AG38: 48 | AH38: 50 | AI38: 66 | AJ38: 50 | AK38: 50 | AL38: 50 | AM38: 50 | AN38: 50 | AO38: 0 | AP38: 0 | AR38: 0 | AS38: 3 | AT38: 3 | AU38: 3 | AV38: 3 | AW38: 3 | AX38: 3 | AY38: 3 | AZ38: 0 | BA38: 0 | BB38: 6 | BC38: 3 | BD38: 6 | BE38: 3 | BF38: 3 | BG38: 3 | BH38: 3 | BI38: 3 | BJ38: 4 | BK38: 8 | BL38: 0 | BM38: 4 | BN38: 4 | BO38: 3 | BP38: 4 | BQ38: 6 | BR38: 6 | BS38: 6 | BT38: 3 | BU38: 6 | BV38: 6 | BW38: 3 | BX38: 3 | BY38: 3 | BZ38: 3 | CA38: 3 | CB38: 0 | CC38: 0 | CE38: 0 | CF38: 0 | CG38: 0 | CH38: 0 | CI38: 0 | CJ38: 0 | CK38: 0 | CL38: 0 | CM38: 0 | CN38: 0 | CO38: 0 | CP38: 0 | CQ38: 0 | CR38: 0 | CS38: 0 | CT38: 0 | CU38: 0 | CV38: 0 | CW38: 0 | CX38: 0 | CY38: 0 | CZ38: 0 | DA38: 0 | DB38: 0 | DC38: 0 | DD38: 0 | DE38: 0 | DF38: 0 | DG38: 0 | DH38: 0 | DI38: 0 | DJ38: 0 | DK38: 0 | DL38: 0 | DM38: 0 | DN38: 0 | DO38: 0 | DP38: 0
A39: Syracuse University | B39: Syracuse | C39: NY | D39: 2823 | E39: 0 | F39: 0 | G39: 50 | H39: 50 | I39: 0 | J39: 0 | K39: 50 | L39: 0 | M39: 0 | N39: 0 | O39: 50 | P39: 0 | Q39: 0 | R39: 0 | S39: 0 | T39: 0 | U39: 0 | V39: 0 | W39: 70 | X39: 0 | Y39: 0 | Z39: 50 | AA39: 0 | AB39: 0 | AC39: 0 | AD39: 50 | AE39: 62 | AF39: 50 | AG39: 63 | AH39: 50 | AI39: 66 | AJ39: 0 | AK39: 0 | AL39: 0 | AM39: 0 | AN39: 0 | AO39: 0 | AP39: 0 | AR39: 0 | AS39: 0 | AT39: 3 | AU39: 3 | AV39: 0 | AW39: 0 | AX39: 6 | AY39: 0 | AZ39: 0 | BA39: 0 | BB39: 3 | BC39: 0 | BD39: 0 | BE39: 0 | BF39: 0 | BG39: 0 | BH39: 0 | BI39: 0 | BJ39: 8 | BK39: 0 | BL39: 0 | BM39: 6 | BN39: 0 | BO39: 0 | BP39: 0 | BQ39: 4 | BR39: 4 | BS39: 4 | BT39: 4 | BU39: 4 | BV39: 4 | BW39: 0 | BX39: 0 | BY39: 0 | BZ39: 0 | CA39: 0 | CB39: 0 | CC39: 0 | CE39: 0 | CF39: 0 | CG39: 0 | CH39: 0 | CI39: 0 | CJ39: 0 | CK39: 0 | CL39: 0 | CM39: 0 | CN39: 0 | CO39: 0 | CP39: 0 | CQ39: 0 | CR39: 0 | CS39: 0 | CT39: 0 | CU39: 0 | CV39: 0 | CW39: 0 | CX39: 0 | CY39: 0 | CZ39: 0 | DA39: 0 | DB39: 0 | DC39: 0 | DD39: 0 | DE39: 0 | DF39: 0 | DG39: 0 | DH39: 0 | DI39: 0 | DJ39: 0 | DK39: 0 | DL39: 0 | DM39: 0 | DN39: 0 | DO39: 0 | DP39: 0
A40: Temple University | B40: Philadelphia | C40: PA | D40: 2906 | E40: 0 | F40: 50 | G40: 50 | H40: 50 | I40: 50 | J40: 0 | K40: 50 | L40: 50 | M40: 0 | N40: 0 | O40: 50 | P40: 50 | Q40: 50 | R40: 0 | S40: 0 | T40: 50 | U40: 50 | V40: 50 | W40: 50 | X40: 50 | Y40: 0 | Z40: 0 | AA40: 0 | AB40: 0 | AC40: 0 | AD40: 0 | AE40: 0 | AF40: 0 | AG40: 0 | AH40: 0 | AI40: 0 | AJ40: 50 | AK40: 0 | AL40: 50 | AM40: 50 | AN40: 50 | AO40: 0 | AP40: 0 | AR40: 0 | AS40: 3 | AT40: 3 | AU40: 3 | AV40: 3 | AW40: 0 | AX40: 3 | AY40: 3 | AZ40: 0 | BA40: 0 | BB40: 3 | BC40: 3 | BD40: 3 | BE40: 0 | BF40: 0 | BG40: 3 | BH40: 3 | BI40: 3 | BJ40: 4 | BK40: 6 | BL40: 0 | BM40: 0 | BN40: 0 | BO40: 0 | BP40: 0 | BQ40: 0 | BR40: 0 | BS40: 0 | BT40: 0 | BU40: 0 | BV40: 0 | BW40: 3 | BX40: 0 | BY40: 3 | BZ40: 3 | CA40: 3 | CB40: 0 | CC40: 0 | CD40: 0 | CE40: 0 | CF40: 0 | CG40: 0 | CH40: 0 | CI40: 0 | CJ40: 0 | CK40: 0 | CL40: 0 | CM40: 0 | CN40: 0 | CO40: 0 | CP40: 0 | CQ40: 0 | CR40: 0 | CS40: 0 | CT40: 0 | CU40: 0 | CV40: 0 | CW40: 0 | CX40: 0 | CY40: 0 | CZ40: 0 | DA40: 0 | DB40: 0 | DC40: 0 | DD40: 0 | DE40: 0 | DF40: 0 | DG40: 0 | DH40: 0 | DI40: 0 | DJ40: 0 | DK40: 0 | DL40: 0 | DM40: 0 | DN40: 0 | DO40: 0 | DP40: 0
A41: Towson University | B41: Towson | C41: MD | D41: 5404 | E41: 50 | F41: 0 | G41: 0 | H41: 0 | I41: 50 | J41: 50 | K41: 0 | L41: 0 | M41: 0 | N41: 60 | O41: 50 | P41: 0 | Q41: 50 | R41: 0 | S41: 50 | T41: 0 | U41: 50 | V41: 50 | W41: 0 | X41: 0 | Y41: 50 | Z41: 0 | AA41: 0 | AB41: 50 | AC41: 0 | AD41: 0 | AE41: 0 | AF41: 0 | AG41: 0 | AH41: 0 | AI41: 0 | AJ41: 50 | AK41: 50 | AL41: 50 | AM41: 0 | AN41: 0 | AO41: 0 | AP41: 0 | AR41: 3 | AS41: 0 | AT41: 0 | AU41: 0 | AV41: 3 | AW41: 6 | AX41: 0 | AY41: 0 | AZ41: 0 | BA41: 3 | BB41: 3 | BC41: 0 | BD41: 3 | BE41: 0 | BF41: 3 | BG41: 0 | BH41: 3 | BI41: 3 | BJ41: 0 | BK41: 0 | BL41: 6 | BM41: 0 | BN41: 0 | BO41: 6 | BP41: 0 | BQ41: 0 | BR41: 0 | BS41: 0 | BT41: 0 | BU41: 0 | BV41: 0 | BW41: 3 | BX41: 3 | BY41: 3 | BZ41: 0 | CA41: 0 | CB41: 0 | CC41: 0 | CE41: 0 | CF41: 0 | CG41: 0 | CH41: 0 | CI41: 0 | CJ41: 0 | CK41: 0 | CL41: 0 | CM41: 0 | CN41: 0 | CO41: 0 | CP41: 0 | CQ41: 0 | CR41: 0 | CS41: 0 | CT41: 0 | CU41: 0 | CV41: 0 | CW41: 0 | CX41: 0 | CY41: 0 | CZ41: 0 | DA41: 0 | DB41: 0 | DC41: 0 | DD41: 0 | DE41: 0 | DF41: 0 | DG41: 0 | DH41: 0 | DI41: 0 | DJ41: 0 | DK41: 0 | DL41: 0 | DM41: 0 | DN41: 0 | DO41: 0 | DP41: 0
A42: Tufts University | B42: Medford | C42: MA | D42: 3901 | E42: 0 | F42: 0 | G42: 0 | H42: 0 | I42: 0 | J42: 0 | K42: 0 | L42: 0 | M42: 0 | N42: 0 | O42: 0 | P42: 0 | Q42: 0 | R42: 0 | S42: 0 | T42: 0 | U42: 0 | V42: 0 | W42: 0 | X42: 0 | Y42: 0 | Z42: 0 | AA42: 0 | AB42: 0 | AC42: 0 | AD42: 0 | AE42: 0 | AF42: 0 | AG42: 0 | AH42: 0 | AI42: 0 | AJ42: 0 | AK42: 0 | AL42: 0 | AM42: 0 | AN42: 0 | AO42: 0 | AP42: 0 | AR42: 0 | AS42: 0 | AT42: 0 | AU42: 0 | AV42: 0 | AW42: 0 | AX42: 0 | AY42: 0 | AZ42: 0 | BA42: 0 | BB42: 0 | BC42: 0 | BD42: 0 | BE42: 0 | BF42: 0 | BG42: 0 | BH42: 0 | BI42: 0 | BJ42: 0 | BK42: 0 | BL42: 0 | BM42: 0 | BN42: 0 | BO42: 0 | BP42: 0 | BQ42: 0 | BR42: 0 | BS42: 0 | BT42: 0 | BU42: 0 | BV42: 0 | BW42: 0 | BX42: 0 | BY42: 0 | BZ42: 0 | CA42: 0 | CB42: 0 | CC42: 0 | CE42: 0 | CF42: 0 | CG42: 0 | CH42: 0 | CI42: 0 | CJ42: 0 | CK42: 0 | CL42: 0 | CM42: 0 | CN42: 0 | CO42: 0 | CP42: 0 | CQ42: 0 | CR42: 0 | CS42: 0 | CT42: 0 | CU42: 0 | CV42: 0 | CW42: 0 | CX42: 0 | CY42: 0 | CZ42: 0 | DA42: 0 | DB42: 0 | DC42: 0 | DD42: 0 | DE42: 0 | DF42: 0 | DG42: 0 | DH42: 0 | DI42: 0 | DJ42: 0 | DK42: 0 | DL42: 0 | DM42: 0 | DN42: 0 | DO42: 0 | DP42: 0
A43: University Of Central Florida | B43: Orlando | C43: FL | D43: 5233 | E43: 50 | F43: 50 | G43: 50 | H43: 50 | I43: 50 | J43: 0 | K43: 50 | L43: 50 | M43: 50 | N43: 50 | O43: 50 | P43: 0 | Q43: 50 | R43: 50 | S43: 50 | T43: 50 | U43: 50 | V43: 50 | W43: 50 | X43: 50 | Y43: 0 | Z43: 50 | AA43: 50 | AB43: 50 | AC43: 50 | AD43: 50 | AE43: 59 | AF43: 50 | AG43: 60 | AH43: 50 | AI43: 63 | AJ43: 50 | AK43: 50 | AL43: 50 | AM43: 50 | AN43: 50 | AO43: 0 | AP43: 0 | AR43: 3 | AS43: 3 | AT43: 3 | AU43: 3 | AV43: 3 | AW43: 0 | AX43: 3 | AY43: 3 | AZ43: 6 | BA43: 6 | BB43: 3 | BC43: 0 | BD43: 3 | BE43: 3 | BF43: 3 | BG43: 3 | BH43: 3 | BI43: 3 | BJ43: 3 | BK43: 3 | BL43: 0 | BM43: 3 | BN43: 3 | BO43: 3 | BP43: 3 | BQ43: 4 | BR43: 8 | BS43: 4 | BT43: 8 | BU43: 4 | BV43: 8 | BW43: 3 | BX43: 3 | BY43: 3 | BZ43: 3 | CA43: 3 | CB43: 0 | CC43: 0 | CE43: 0 | CF43: 0 | CG43: 0 | CH43: 0 | CI43: 0 | CJ43: 0 | CK43: 0 | CL43: 0 | CM43: 0 | CN43: 0 | CO43: 0 | CP43: 0 | CQ43: 0 | CR43: 0 | CS43: 0 | CT43: 0 | CU43: 0 | CV43: 0 | CW43: 0 | CX43: 0 | CY43: 0 | CZ43: 0 | DA43: 0 | DB43: 0 | DC43: 0 | DD43: 0 | DE43: 0 | DF43: 0 | DG43: 0 | DH43: 0 | DI43: 0 | DJ43: 0 | DK43: 0 | DL43: 0 | DM43: 0 | DN43: 0 | DO43: 0 | DP43: 0
A44: Purdue University Calumet - Crown Point | B44: Crown Point | C44: IN | D44: 4730 | E44: 50 | F44: 50 | G44: 50 | H44: 50 | I44: 50 | J44: 50 | K44: 50 | L44: 50 | M44: 50 | N44: 50 | O44: 50 | P44: 50 | Q44: 50 | R44: 50 | S44: 50 | T44: 50 | U44: 50 | V44: 50 | W44: 50 | X44: 50 | Y44: 50 | Z44: 50 | AA44: 50 | AB44: 50 | AC44: 50 | AD44: 50 | AE44: 64 | AF44: 50 | AG44: 64 | AH44: 50 | AI44: 64 | AJ44: 50 | AK44: 50 | AL44: 50 | AM44: 45 | AN44: 50 | AO44: 0 | AP44: 0 | AR44: 3 | AS44: 3 | AT44: 3 | AU44: 3 | AV44: 3 | AW44: 3 | AX44: 3 | AY44: 3 | AZ44: 3 | BA44: 3 | BB44: 6 | BC44: 3 | BD44: 3 | BE44: 3 | BF44: 3 | BG44: 3 | BH44: 3 | BI44: 3 | BJ44: 8 | BK44: 3 | BL44: 3 | BM44: 3 | BN44: 3 | BO44: 3 | BP44: 3 | BQ44: 3 | BR44: 9 | BS44: 3 | BT44: 9 | BU44: 3 | BV44: 9 | BW44: 3 | BX44: 3 | BY44: 3 | BZ44: 3 | CA44: 3 | CB44: 0 | CC44: 0 | CE44: 0 | CF44: 0 | CG44: 0 | CH44: 0 | CI44: 0 | CJ44: 0 | CK44: 0 | CL44: 0 | CM44: 0 | CN44: 0 | CO44: 0 | CP44: 0 | CQ44: 0 | CR44: 0 | CS44: 0 | CT44: 0 | CU44: 0 | CV44: 0 | CW44: 0 | CX44: 0 | CY44: 0 | CZ44: 0 | DA44: 0 | DB44: 0 | DC44: 0 | DD44: 0 | DE44: 0 | DF44: 0 | DG44: 0 | DH44: 0 | DI44: 0 | DJ44: 0 | DK44: 0 | DL44: 0 | DM44: 0 | DN44: 0 | DO44: 0 | DP44: 0
